Workbook

Sheet DD
B1: Ville | C1: Khouribga | G1: Mois | H1: 01
B3: Date | C3: Etat du ciel observé | G3: Vent moyen observé : Direction e force | O3: Température observée | Q3: Phénomènes Observés
G4: 06h-08h | I4: 09h-11h | K4: 12h-14h | M4: 15h-18h
C5: 06h-08h | D5: 09h-11h | E5: 12h-14h | F5: 15h-18h | G5: DD | H5: ff | I5: DD | J5: ff | K5: DD | L5: ff | M5: DD | N5: ff | O5: Tmax | P5: Tmin
B6: 2023-01-01 | C6: 3 | D6: 3 | E6: 3 | F6: 4 | G6: 346.66667 | H6: 4.6666667 | I6: 246.66667 | J6: 4.3333333 | K6: 160 | L6: 4 | M6: 255 | N6: 3.75 | O6: 19 | P6: 9.4 | Q6: Néant
B7: 2023-01-02 | C7: 1 | D7: 1 | E7: 1 | F7: 1 | G7: 66.666667 | H7: 5 | I7: 110 | J7: 5.6666667 | K7: 190 | L7: 2.6666667 | M7: 20 | N7: 5.25 | O7: 20.5 | P7: 8 | Q7: Néant
B8: 2023-01-03 | C8: 1 | D8: 2 | E8: 2 | F8: 2 | G8: 106.66667 | H8: 3.3333333 | I8: 80 | J8: 2.3333333 | K8: 36.666667 | L8: 5 | M8: 20 | N8: 11 | O8: 18.4 | P8: 8.9 | Q8: Néant
B9: 2023-01-04 | C9: 1 | D9: 1 | E9: 1 | F9: 2 | G9: 76.666667 | H9: 2.6666667 | I9: 96.666667 | J9: 4.3333333 | K9: 133.33333 | L9: 3 | M9: 15 | N9: 6.75 | O9: 19.5 | P9: 6.8 | Q9: Néant
B10: 2023-01-05 | C10: 1 | D10: 1 | E10: 1 | F10: 1 | G10: 113.33333 | H10: 6 | I10: 156.66667 | J10: 4.3333333 | K10: 213.33333 | L10: 4.3333333 | M10: 287.5 | N10: 5.25 | O10: 19.3 | P10: 9 | Q10: Néant
B11: 2023-01-06 | C11: 1 | D11: 1 | E11: 1 | F11: 1 | G11: 116.66667 | H11: 4.6666667 | I11: 150 | J11: 4 | K11: 226.66667 | L11: 4.6666667 | M11: 272.5 | N11: 4.75 | O11: 18.1 | P11: 2.2 | Q11: Néant
B12: 2023-01-07 | C12: 1 | D12: 1 | E12: 1 | F12: 1 | G12: 143.33333 | H12: 5.6666667 | I12: 150 | J12: 5 | K12: 316.66667 | L12: 4.3333333 | M12: 236.66667 | N12: 4 | O12: 18.4 | P12: 7 | Q12: Néant
B13: 2023-01-08 | C13: 1 | D13: 1 | E13: 1 | F13: 1 | G13: 116.66667 | H13: 5 | I13: 156.66667 | J13: 5 | K13: 223.33333 | L13: 6 | M13: 295 | N13: 6.5 | O13: 17.7 | P13: 6.1 | Q13: Néant
B14: 2023-01-09 | C14: 1 | D14: 2 | E14: 3 | F14: 2 | G14: 76.666667 | H14: 3.6666667 | I14: 130 | J14: 4 | K14: 243.33333 | L14: 6 | M14: 20 | N14: 7.5 | O14: 16.9 | P14: 6.8 | Q14: Néant
B15: 2023-01-10 | C15: 1 | D15: 1 | E15: 1 | F15: 1 | G15: 46.666667 | H15: 4.3333333 | I15: 50 | J15: 4.3333333 | K15: 20 | L15: 5.3333333 | M15: 25 | N15: 8.5 | O15: 19.4 | P15: 6.9 | Q15: Néant
B16: 2023-01-11 | C16: 3 | D16: 2 | E16: 2 | F16: 2 | G16: 30 | H16: 9.3333333 | I16: 36.666667 | J16: 10.666667 | K16: 33.333333 | L16: 10.333333 | M16: 30 | N16: 10 | O16: 15.7 | P16: 7 | Q16: Brume/Brouillard - Brouillard/Brume
B17: 2023-01-12 | C17: 3 | D17: 1 | E17: 1 | F17: 2 | G17: 46.666667 | H17: 7.6666667 | I17: 46.666667 | J17: 9.6666667 | K17: 43.333333 | L17: 7 | M17: 32.5 | N17: 10.75 | O17: 15.1 | P17: 8.1 | Q17: Néant
... B36: 2023-01-31 | C36: 3 | D36: 2 | E36: 2 | F36: 2 | G36: 103.33333 | H36: 6 | I36: 123.33333 | J36: 6.3333333 | K36: 116.66667 | L36: 7.3333333 | M36: 187.5 | N36: 8.75 | O36: 15.3 | P36: 15.3 | Q36: Néant
B40: Date | C40: Etat du ciel prévu | I40: Vent prévu: Directions et forces | U40: Température prévue | X40: Phénomènes prévus
C41: 12h-24h | E41: 24h-36h | G41: 36h-48h | I41: 12h-24h | M41: 24h-36h | Q41: 36h-48h | U41: 12h-24h | V41: 24h-36h | W41: 36h-48h | X41: 12h-24h | Y41: 24h-36h
C42: >>Devenant>> | E42: >>Devenant>> | G42: >>Devenant>> | I42: DD1 | J42: ff | K42: DD2 | L42: FF/Raf | M42: DD2 | N42: ff | O42: DD3 | P42: FF/Raf | Q42: DD2 | R42: ff | S42: DD3 | T42: FF/Raf | U42: Tmax | V42: Tmax | W42: Tmin
B43: 2022-12-31 | C43: 2 | D43: 2 | E43: 2 | F43: 1 | G43: 1 | H43: 1 | I43: 180 | J43: 2 | K43: 315 | L43: 20 | M43: 0 | N43: 2 | O43: 90 | P43: 20 | Q43: 0 | R43: 2 | S43: 45 | T43: 25 | U43: 21 | V43: 20 | W43: 6 | X43: Néant | Y43: Néant
B44: 2023-01-01 | C44: 2 | D44: 1 | E44: 1 | F44: 1 | G44: 1 | H44: 1 | I44: 225 | J44: 2 | K44: 0 | L44: 25 | M44: 90 | N44: 2 | O44: 90 | P44: 25 | Q44: 0 | R44: 2 | S44: 0 | T44: 40 | U44: 19 | V44: 20 | W44: 5 | X44: Néant | Y44: Néant
B45: 2023-01-02 | C45: 1 | D45: 1 | E45: 1 | F45: 1 | G45: 1 | H45: 1 | I45: 0 | J45: 2 | K45: 0 | L45: 25 | M45: 0 | N45: 2 | O45: 0 | P45: 15 | Q45: 0 | R45: 2 | S45: 0 | T45: 35 | U45: 19 | V45: 20 | W45: 7 | X45: Néant | Y45: Néant
B46: 2023-01-03 | C46: 2 | D46: 1 | E46: 1 | F46: 1 | G46: 1 | H46: 1 | I46: 0 | J46: 2 | K46: 0 | L46: 35 | M46: 45 | N46: 2 | O46: 45 | P46: 20 | Q46: 0 | R46: 2 | S46: 315 | T46: 25 | U46: 20 | V46: 19 | W46: 7 | X46: Néant | Y46: Néant
B47: 2023-01-04 | C47: 1 | D47: 1 | E47: 1 | F47: 1 | G47: 1 | H47: 1 | I47: 45 | J47: 2 | K47: 0 | L47: 30 | M47: 90 | N47: 2 | O47: 90 | P47: 20 | Q47: 225 | R47: 2 | S47: 270 | T47: 25 | U47: 19 | V47: 19 | W47: 6 | X47: Néant | Y47: Néant
B48: 2023-01-05 | C48: 1 | D48: 1 | E48: 1 | F48: 1 | G48: 1 | H48: 1 | I48: 225 | J48: 2 | K48: 0 | L48: 20 | M48: 90 | N48: 2 | O48: 45 | P48: 15 | Q48: 270 | R48: 2 | S48: 225 | T48: 20 | U48: 20 | V48: 19 | W48: 7 | X48: Néant | Y48: Néant
B49: 2023-01-06 | C49: 1 | D49: 1 | E49: 1 | F49: 1 | G49: 1 | H49: 1 | I49: 270 | J49: 2 | K49: 270 | L49: 25 | M49: 90 | N49: 2 | O49: 45 | P49: 15 | Q49: 225 | R49: 2 | S49: 0 | T49: 25 | U49: 18 | V49: 18 | W49: 6 | X49: Néant | Y49: Néant
B50: 2023-01-07 | C50: 1 | D50: 1 | E50: 1 | F50: 1 | G50: 1 | H50: 1 | I50: 225 | J50: 2 | K50: 315 | L50: 25 | M50: 90 | N50: 2 | O50: 90 | P50: 15 | Q50: 270 | R50: 2 | S50: 270 | T50: 25 | U50: 18 | V50: 18 | W50: 6 | X50: Néant | Y50: Brume/Brouillard
B51: 2023-01-08 | C51: 1 | D51: 1 | E51: 1 | F51: 1 | G51: 1 | H51: 2 | I51: 270 | J51: 2 | K51: 135 | L51: 30 | M51: 45 | N51: 2 | O51: 45 | P51: 15 | Q51: 0 | R51: 2 | S51: 0 | T51: 25 | U51: 18 | V51: 20 | W51: 5 | X51: Néant | Y51: Néant
B52: 2023-01-09 | C52: 1 | D52: 1 | E52: 1 | F52: 1 | G52: 1 | H52: 1 | I52: 0 | J52: 2 | K52: 45 | L52: 30 | M52: 45 | N52: 2 | O52: 45 | P52: 20 | Q52: 0 | R52: 2 | S52: 0 | T52: 25 | U52: 19 | V52: 21 | W52: 6 | X52: Néant | Y52: Brume/Brouillard
B53: 2023-01-10 | C53: 1 | D53: 1 | E53: 3 | F53: 3 | G53: 1 | H53: 2 | I53: 0 | J53: 2 | K53: 0 | L53: 25 | M53: 0 | N53: 2 | O53: 0 | P53: 15 | Q53: 0 | R53: 5 | S53: 0 | T53: 25 | U53: 21 | V53: 18 | W53: 7 | X53: Néant | Y53: Néant
B54: 2023-01-11 | C54: 2 | D54: 1 | E54: 2 | F54: 2 | G54: 3 | H54: 2 | I54: 0 | J54: 5 | K54: 0 | L54: 30 | M54: 45 | N54: 5 | O54: 45 | P54: 25 | Q54: 0 | R54: 5 | S54: 0 | T54: 30 | U54: 17 | V54: 19 | W54: 6 | X54: Néant | Y54: Brume/Brouillard
... B74: 2023-01-31 | C74: 1 | D74: 1 | E74: 1 | F74: 1 | G74: 2 | H74: 1 | I74: 45 | J74: 2 | K74: 0 | L74: 30 | M74: 90 | N74: 2 | O74: 45 | P74: 25 | Q74: 0 | R74: 2 | S74: 0 | T74: 30 | U74: 15 | V74: 16 | W74: 3 | X74: Néant | Y74: Néant
B79: Date | C79: Nébulosité observée | P79: Nébulosité prévue | V79: Vent : Direction et Force
P80: 12h-24h | R80: 24h-36h | T80: 36h-48h | V80: DD | W80: ff | X80: DD | Y80: ff | Z80: DD | AA80: ff | AB80: DD | AC80: ff | AD80: DD | AE80: ff | AF80: DD | AG80: ff | AH80: DD | AI80: ff | AJ80: DD | AK80: ff | AL80: DD | AM80: ff | AN80: DD | AO80: ff | AP80: DD | AQ80: ff | AR80: DD | AS80: ff | AT80: DD | AU80: ff
C81: 06h | D81: 07h | E81: 08h | F81: 09h | G81: 10h | H81: 11h | I81: 12h | J81: 13h | K81: 14h | L81: 15h | M81: 16h | N81: 17h | O81: 18h | P81: >>Devenant>> | R81: >>Devenant>> | T81: >>Devenant>> | V81: 06h | W81: 06h | X81: 07h | Y81: 07h | Z81: 08h | AA81: 10h | AB81: 09h | AC81: 09h | AD81: 10h | AE81: 10h | AF81: 11h | AG81: 11h | AH81: 12h | AI81: 12h | AJ81: 13h | AK81: 13h | AL81: 14h | AM81: 14h | AN81: 15h | AO81: 15h | AP81: 16h | AQ81: 16h | AR81: 17h | AS81: 17h | AT81: 18h | AU81: 18h
B82: 2022-12-31 | P82: 3 | Q82: 3 | R82: 3 | S82: 1 | T82: 1 | U82: 1
B83: 2023-01-01 | C83: 4 | D83: 5 | E83: 6 | F83: 7 | G83: 5 | H83: 5 | I83: 5 | J83: 5 | K83: 5 | L83: 7 | M83: 7 | N83: 7 | O83: 7 | P83: 3 | Q83: 1 | R83: 1 | S83: 1 | T83: 1 | U83: 0 | V83: 330 | W83: 3 | X83: 350 | Y83: 5 | Z83: 360 | AA83: 6 | AB83: 20 | AC83: 4 | AD83: 360 | AE83: 6 | AF83: 360 | AG83: 3 | AH83: 170 | AI83: 3 | AJ83: 160 | AK83: 6 | AL83: 150 | AM83: 3 | AN83: 210 | AO83: 5 | AP83: 210 | AQ83: 4 | AR83: 240 | AS83: 3 | AT83: 360 | AU83: 3
B84: 2023-01-02 | C84: 2 | D84: 2 | E84: 2 | F84: 1 | G84: 1 | H84: 1 | I84: 2 | J84: 2 | K84: 2 | L84: 2 | M84: 2 | N84: 2 | O84: 2 | P84: 0 | Q84: 0 | R84: 0 | S84: 0 | T84: 2 | U84: 1 | V84: 60 | W84: 6 | X84: 60 | Y84: 5 | Z84: 80 | AA84: 4 | AB84: 90 | AC84: 2 | AD84: 110 | AE84: 7 | AF84: 130 | AG84: 8 | AH84: 160 | AI84: 4 | AJ84: 60 | AK84: 2 | AL84: 350 | AM84: 2 | AN84: 30 | AO84: 4 | AP84: 20 | AQ84: 6 | AR84: 20 | AS84: 5 | AT84: 10 | AU84: 6
B85: 2023-01-03 | C85: 0 | D85: 0 | E85: 0 | F85: 2 | G85: 2 | H85: 4 | I85: 4 | J85: 4 | K85: 4 | L85: 4 | M85: 2 | N85: 2 | O85: 3 | P85: 3 | Q85: 1 | R85: 1 | S85: 1 | T85: 1 | U85: 2 | V85: 70 | W85: 3 | X85: 130 | Y85: 4 | Z85: 120 | AA85: 3 | AB85: 110 | AC85: 3 | AD85: 110 | AE85: 3 | AF85: 20 | AG85: 1 | AH85: 80 | AI85: 1 | AJ85: 10 | AK85: 7 | AL85: 20 | AM85: 7 | AN85: 10 | AO85: 10 | AP85: 10 | AQ85: 12 | AR85: 30 | AS85: 11 | AT85: 30 | AU85: 11
...

Sheet Data
B1: Ville | G1: Mois
B3: Date | C3: Etat du ciel observé | G3: Vent moyen observé : Direction e force | O3: Température observée | Q3: Phénomènes Observés
G4: 06h-08h | I4: 09h-11h | K4: 12h-14h | M4: 15h-18h
C5: 06h-08h | D5: 09h-11h | E5: 12h-14h | F5: 15h-18h | G5: DD | H5: ff | I5: DD | J5: ff | K5: DD | L5: ff | M5: DD | N5: ff | O5: Tmax | P5: Tmin
B40: Date | C40: Etat du ciel prévu | I40: Vent prévu: Directions et forces | U40: Température prévue | X40: Phénomènes prévus
C41: 12h-24h | E41: 24h-36h | G41: 36h-48h | I41: 12h-24h | M41: 24h-36h | Q41: 36h-48h | U41: 12h-24h | V41: 24h-36h | W41: 36h-48h | X41: 12h-24h | Y41: 24h-36h
C42: >>Devenant>> | E42: >>Devenant>> | G42: >>Devenant>> | I42: DD1 | J42: ff | K42: DD2 | L42: FF/Raf | M42: DD2 | N42: ff | O42: DD3 | P42: FF/Raf | Q42: DD2 | R42: ff | S42: DD3 | T42: FF/Raf | U42: Tmax | V42: Tmax | W42: Tmin
B79: Date | C79: Nébulosité observée | P79: Nébulosité prévue | V79: Vent : Direction et Force
P80: 12h-24h | R80: 24h-36h | T80: 36h-48h | V80: DD | W80: ff | X80: DD | Y80: ff | Z80: DD | AA80: ff | AB80: DD | AC80: ff | AD80: DD | AE80: ff | AF80: DD | AG80: ff | AH80: DD | AI80: ff | AJ80: DD | AK80: ff | AL80: DD | AM80: ff | AN80: DD | AO80: ff | AP80: DD | AQ80: ff | AR80: DD | AS80: ff | AT80: DD | AU80: ff
C81: 06h | D81: 07h | E81: 08h | F81: 09h | G81: 10h | H81: 11h | I81: 12h | J81: 13h | K81: 14h | L81: 15h | M81: 16h | N81: 17h | O81: 18h | P81: >>Devenant>> | R81: >>Devenant>> | T81: >>Devenant>> | V81: 06h | W81: 06h | X81: 07h | Y81: 07h | Z81: 08h | AA81: 10h | AB81: 09h | AC81: 09h | AD81: 10h | AE81: 10h | AF81: 11h | AG81: 11h | AH81: 12h | AI81: 12h | AJ81: 13h | AK81: 13h | AL81: 14h | AM81: 14h | AN81: 15h | AO81: 15h | AP81: 16h | AQ81: 16h | AR81: 17h | AS81: 17h | AT81: 18h | AU81: 18h

Sheet Etat du Ciel
B2: =Data!C1 -> 0 | I2: Contrôle de l'état du ciel
B5: Date | C5: 06h-08h | H5: 09h-11h | M5: 12h-14h | R5: 15h-18h | W5: Score 24 | X5: Score 48 | Y5: Taux de réussite 24 | Z5: Taux de réussite 48 | AB5: Taux de réussite final 24 | AC5: Taux de réussite final 48
C6: Obs | D6: Pré 00-12 | E6: Pré 24-36 | F6: Score 24 | G6: Score 48 | H6: Obs | I6: Pré 00-12 | J6: Pré 24-36 | K6: Score 24 | L6: Score 48 | M6: Obs | N6: Pré 12-24 | O6: Pré 36-48 | P6: Score 24 | Q6: Score 48 | R6: Obs | S6: Pré 12-24 | T6: Pré 36-48 | U6: Score 24 | V6: Score 48
B7: 1 | C7: =IF(ISBLANK(Data!C6),"",Data!C6) | E7: =IF(ISBLANK(Data!F43),"",IF(Data!F43=Data!E43,Data!F43,IF(MIN(ABS(Data!F43-Data!C6),ABS(Data!E43-Data!C6))=ABS(Data!F43-Data!C6),Data!F43,IF(MIN(ABS(Data!F43-Data!C6),ABS(Data!E43-Data!C6))=ABS(Data!E43-Data!C6),Data!E43,"")))) | F7: =IF(OR(C7="",D7=""),1,IF(ABS(D7-C7)>=3,0,IF(ABS(D7-C7)=2,0.5,IF(ABS(D7-C7)=1,0.75,1)))) -> 1 | G7: =IF(OR(C7="",E7=""),1,IF(ABS(E7-C7)>=3,0,IF(ABS(E7-C7)=2,0.5,IF(ABS(E7-C7)=1,0.75,1)))) -> 1 | H7: =IF(ISBLANK(Data!D6),"",Data!D6) | J7: =IF(ISBLANK(Data!F43),"",IF(Data!F43=Data!G43,Data!F43,IF(MIN(ABS(Data!F43-Data!E6),ABS(Data!G43-Data!E6))=ABS(Data!F43-Data!E6),Data!F43,IF(MIN(ABS(Data!F43-Data!E6),ABS(Data!G43-Data!E6))=ABS(Data!G43-Data!E6),Data!G43,"")))) | K7: =IF(OR(H7="",I7=""),1,IF(ABS(I7-H7)>=3,0,IF(ABS(I7-H7)=2,0.5,IF(ABS(I7-H7)=1,0.75,1)))) -> 1 | L7: =IF(OR(H7="",J7=""),1,IF(ABS(J7-H7)>=3,0,IF(ABS(J7-H7)=2,0.5,IF(ABS(J7-H7)=1,0.75,1)))) -> 1 | M7: =IF(ISBLANK(Data!E6),"",Data!E6) | N7: =IF(ISBLANK(Data!C44),"",IF(Data!C44=Data!D44,Data!C44,IF(MIN(ABS(Data!C44-Data!E6),ABS(Data!D44-Data!E6))=ABS(Data!C44-Data!E6),Data!C44,IF(MIN(ABS(Data!C44-Data!E6),ABS(Data!D44-Data!E6))=ABS(Data!D44-Data!E6),Data!D44,"")))) | O7: =IF(ISBLANK(Data!G43),"",IF(Data!G43=Data!F43,Data!G43,IF(MIN(ABS(Data!G43-Data!E6),ABS(Data!F43-Data!E6))=ABS(Data!G43-Data!E6),Data!G43,IF(MIN(ABS(Data!G43-Data!E6),ABS(Data!F43-Data!E6))=ABS(Data!F43-Data!E6),Data!F43,"")))) | P7: =IF(OR(M7="",N7=""),1,IF(ABS(N7-M7)>=3,0,IF(ABS(N7-M7)=2,0.5,IF(ABS(N7-M7)=1,0.75,1)))) -> 1 | Q7: =IF(OR(M7="",O7=""),1,IF(ABS(O7-M7)>=3,0,IF(ABS(O7-M7)=2,0.5,IF(ABS(O7-M7)=1,0.75,1)))) -> 1 | R7: =IF(ISBLANK(Data!F6),"",Data!F6) | S7: =IF(ISBLANK(Data!C44),"",IF(Data!C44=Data!D44,Data!C44,IF(MIN(ABS(Data!C44-Data!E6),ABS(Data!D44-Data!E6))=ABS(Data!C44-Data!E6),Data!C44,IF(MIN(ABS(Data!C44-Data!E6),ABS(Data!D44-Data!E6))=ABS(Data!D44-Data!E6),Data!D44,"")))) | T7: =IF(ISBLANK(Data!G43),"",IF(Data!G43=Data!G43,Data!G43,IF(MIN(ABS(Data!G43-Data!F6),ABS(Data!G43-Data!F6))=ABS(Data!G43-Data!F6),Data!G43,IF(MIN(ABS(Data!G43-Data!F6),ABS(Data!G43-Data!F6))=ABS(Data!G43-Data!F6),Data!G43,"")))) | U7: =IF(OR(R7="",S7=""),1,IF(ABS(S7-R7)>=3,0,IF(ABS(S7-R7)=2,0.5,IF(ABS(S7-R7)=1,0.75,1)))) -> 1 | V7: =IF(OR(R7="",T7=""),1,IF(ABS(T7-R7)>=3,0,IF(ABS(T7-R7)=2,0.5,IF(ABS(T7-R7)=1,0.75,1)))) -> 1 | W7: =AVERAGE(F7,K7,P7,U7) -> 1 | X7: =AVERAGE(G7,L7,Q7,V7) -> 1 | Y7: =+IF(W7>=0.8,1,IF(W7>=0.65,0.75,IF(W7>=0.5,0.5,IF(W7>=0.35,0.25,0)))) -> 1 | Z7: =+IF(X7>=0.8,1,IF(X7>=0.65,0.75,IF(X7>=0.5,0.5,IF(X7>=0.35,0.25,0)))) -> 1 | AB7: =AVERAGE(Y7:Y37) -> 1 | AC7: =AVERAGE(Z7:Z37) -> 1
B8: =B7+1 -> 2 | C8: =IF(ISBLANK(Data!C7),"",Data!C7) | E8: =IF(ISBLANK(Data!F44),"",IF(Data!F44=Data!E44,Data!F44,IF(MIN(ABS(Data!F44-Data!C7),ABS(Data!E44-Data!C7))=ABS(Data!F44-Data!C7),Data!F44,IF(MIN(ABS(Data!F44-Data!C7),ABS(Data!E44-Data!C7))=ABS(Data!E44-Data!C7),Data!E44,"")))) | F8: =IF(OR(C8="",D8=""),1,IF(ABS(D8-C8)>=3,0,IF(ABS(D8-C8)=2,0.5,IF(ABS(D8-C8)=1,0.75,1)))) -> 1 | G8: =IF(OR(C8="",E8=""),1,IF(ABS(E8-C8)>=3,0,IF(ABS(E8-C8)=2,0.5,IF(ABS(E8-C8)=1,0.75,1)))) -> 1 | H8: =IF(ISBLANK(Data!D7),"",Data!D7) | J8: =IF(ISBLANK(Data!F44),"",IF(Data!F44=Data!G44,Data!F44,IF(MIN(ABS(Data!F44-Data!E7),ABS(Data!G44-Data!E7))=ABS(Data!F44-Data!E7),Data!F44,IF(MIN(ABS(Data!F44-Data!E7),ABS(Data!G44-Data!E7))=ABS(Data!G44-Data!E7),Data!G44,"")))) | K8: =IF(OR(H8="",I8=""),1,IF(ABS(I8-H8)>=3,0,IF(ABS(I8-H8)=2,0.5,IF(ABS(I8-H8)=1,0.75,1)))) -> 1 | L8: =IF(OR(H8="",J8=""),1,IF(ABS(J8-H8)>=3,0,IF(ABS(J8-H8)=2,0.5,IF(ABS(J8-H8)=1,0.75,1)))) -> 1 | M8: =IF(ISBLANK(Data!E7),"",Data!E7) | N8: =IF(ISBLANK(Data!C45),"",IF(Data!C45=Data!D45,Data!C45,IF(MIN(ABS(Data!C45-Data!E7),ABS(Data!D45-Data!E7))=ABS(Data!C45-Data!E7),Data!C45,IF(MIN(ABS(Data!C45-Data!E7),ABS(Data!D45-Data!E7))=ABS(Data!D45-Data!E7),Data!D45,"")))) | O8: =IF(ISBLANK(Data!G44),"",IF(Data!G44=Data!F44,Data!G44,IF(MIN(ABS(Data!G44-Data!E7),ABS(Data!F44-Data!E7))=ABS(Data!G44-Data!E7),Data!G44,IF(MIN(ABS(Data!G44-Data!E7),ABS(Data!F44-Data!E7))=ABS(Data!F44-Data!E7),Data!F44,"")))) | P8: =IF(OR(M8="",N8=""),1,IF(ABS(N8-M8)>=3,0,IF(ABS(N8-M8)=2,0.5,IF(ABS(N8-M8)=1,0.75,1)))) -> 1 | Q8: =IF(OR(M8="",O8=""),1,IF(ABS(O8-M8)>=3,0,IF(ABS(O8-M8)=2,0.5,IF(ABS(O8-M8)=1,0.75,1)))) -> 1 | R8: =IF(ISBLANK(Data!F7),"",Data!F7) | S8: =IF(ISBLANK(Data!C45),"",IF(Data!C45=Data!D45,Data!C45,IF(MIN(ABS(Data!C45-Data!E7),ABS(Data!D45-Data!E7))=ABS(Data!C45-Data!E7),Data!C45,IF(MIN(ABS(Data!C45-Data!E7),ABS(Data!D45-Data!E7))=ABS(Data!D45-Data!E7),Data!D45,"")))) | T8: =IF(ISBLANK(Data!G44),"",IF(Data!G44=Data!G44,Data!G44,IF(MIN(ABS(Data!G44-Data!F7),ABS(Data!G44-Data!F7))=ABS(Data!G44-Data!F7),Data!G44,IF(MIN(ABS(Data!G44-Data!F7),ABS(Data!G44-Data!F7))=ABS(Data!G44-Data!F7),Data!G44,"")))) | U8: =IF(OR(R8="",S8=""),1,IF(ABS(S8-R8)>=3,0,IF(ABS(S8-R8)=2,0.5,IF(ABS(S8-R8)=1,0.75,1)))) -> 1 | V8: =IF(OR(R8="",T8=""),1,IF(ABS(T8-R8)>=3,0,IF(ABS(T8-R8)=2,0.5,IF(ABS(T8-R8)=1,0.75,1)))) -> 1 | W8: =AVERAGE(F8,K8,P8,U8) -> 1 | X8: =AVERAGE(G8,L8,Q8,V8) -> 1 | Y8: =+IF(W8>=0.8,1,IF(W8>=0.65,0.75,IF(W8>=0.5,0.5,IF(W8>=0.35,0.25,0)))) -> 1 | Z8: =+IF(X8>=0.8,1,IF(X8>=0.65,0.75,IF(X8>=0.5,0.5,IF(X8>=0.35,0.25,0)))) -> 1
B9: =B8+1 -> 3 | C9: =IF(ISBLANK(Data!C8),"",Data!C8) | E9: =IF(ISBLANK(Data!F45),"",IF(Data!F45=Data!E45,Data!F45,IF(MIN(ABS(Data!F45-Data!C8),ABS(Data!E45-Data!C8))=ABS(Data!F45-Data!C8),Data!F45,IF(MIN(ABS(Data!F45-Data!C8),ABS(Data!E45-Data!C8))=ABS(Data!E45-Data!C8),Data!E45,"")))) | F9: =IF(OR(C9="",D9=""),1,IF(ABS(D9-C9)>=3,0,IF(ABS(D9-C9)=2,0.5,IF(ABS(D9-C9)=1,0.75,1)))) -> 1 | G9: =IF(OR(C9="",E9=""),1,IF(ABS(E9-C9)>=3,0,IF(ABS(E9-C9)=2,0.5,IF(ABS(E9-C9)=1,0.75,1)))) -> 1 | H9: =IF(ISBLANK(Data!D8),"",Data!D8) | J9: =IF(ISBLANK(Data!F45),"",IF(Data!F45=Data!G45,Data!F45,IF(MIN(ABS(Data!F45-Data!E8),ABS(Data!G45-Data!E8))=ABS(Data!F45-Data!E8),Data!F45,IF(MIN(ABS(Data!F45-Data!E8),ABS(Data!G45-Data!E8))=ABS(Data!G45-Data!E8),Data!G45,"")))) | K9: =IF(OR(H9="",I9=""),1,IF(ABS(I9-H9)>=3,0,IF(ABS(I9-H9)=2,0.5,IF(ABS(I9-H9)=1,0.75,1)))) -> 1 | L9: =IF(OR(H9="",J9=""),1,IF(ABS(J9-H9)>=3,0,IF(ABS(J9-H9)=2,0.5,IF(ABS(J9-H9)=1,0.75,1)))) -> 1 | M9: =IF(ISBLANK(Data!E8),"",Data!E8) | N9: =IF(ISBLANK(Data!C46),"",IF(Data!C46=Data!D46,Data!C46,IF(MIN(ABS(Data!C46-Data!E8),ABS(Data!D46-Data!E8))=ABS(Data!C46-Data!E8),Data!C46,IF(MIN(ABS(Data!C46-Data!E8),ABS(Data!D46-Data!E8))=ABS(Data!D46-Data!E8),Data!D46,"")))) | O9: =IF(ISBLANK(Data!G45),"",IF(Data!G45=Data!F45,Data!G45,IF(MIN(ABS(Data!G45-Data!E8),ABS(Data!F45-Data!E8))=ABS(Data!G45-Data!E8),Data!G45,IF(MIN(ABS(Data!G45-Data!E8),ABS(Data!F45-Data!E8))=ABS(Data!F45-Data!E8),Data!F45,"")))) | P9: =IF(OR(M9="",N9=""),1,IF(ABS(N9-M9)>=3,0,IF(ABS(N9-M9)=2,0.5,IF(ABS(N9-M9)=1,0.75,1)))) -> 1 | Q9: =IF(OR(M9="",O9=""),1,IF(ABS(O9-M9)>=3,0,IF(ABS(O9-M9)=2,0.5,IF(ABS(O9-M9)=1,0.75,1)))) -> 1 | R9: =IF(ISBLANK(Data!F8),"",Data!F8) | S9: =IF(ISBLANK(Data!C46),"",IF(Data!C46=Data!D46,Data!C46,IF(MIN(ABS(Data!C46-Data!E8),ABS(Data!D46-Data!E8))=ABS(Data!C46-Data!E8),Data!C46,IF(MIN(ABS(Data!C46-Data!E8),ABS(Data!D46-Data!E8))=ABS(Data!D46-Data!E8),Data!D46,"")))) | T9: =IF(ISBLANK(Data!G45),"",IF(Data!G45=Data!G45,Data!G45,IF(MIN(ABS(Data!G45-Data!F8),ABS(Data!G45-Data!F8))=ABS(Data!G45-Data!F8),Data!G45,IF(MIN(ABS(Data!G45-Data!F8),ABS(Data!G45-Data!F8))=ABS(Data!G45-Data!F8),Data!G45,"")))) | U9: =IF(OR(R9="",S9=""),1,IF(ABS(S9-R9)>=3,0,IF(ABS(S9-R9)=2,0.5,IF(ABS(S9-R9)=1,0.75,1)))) -> 1 | V9: =IF(OR(R9="",T9=""),1,IF(ABS(T9-R9)>=3,0,IF(ABS(T9-R9)=2,0.5,IF(ABS(T9-R9)=1,0.75,1)))) -> 1 | W9: =AVERAGE(F9,K9,P9,U9) -> 1 | X9: =AVERAGE(G9,L9,Q9,V9) -> 1 | Y9: =+IF(W9>=0.8,1,IF(W9>=0.65,0.75,IF(W9>=0.5,0.5,IF(W9>=0.35,0.25,0)))) -> 1 | Z9: =+IF(X9>=0.8,1,IF(X9>=0.65,0.75,IF(X9>=0.5,0.5,IF(X9>=0.35,0.25,0)))) -> 1
B10: =B9+1 -> 4 | C10: =IF(ISBLANK(Data!C9),"",Data!C9) | E10: =IF(ISBLANK(Data!F46),"",IF(Data!F46=Data!E46,Data!F46,IF(MIN(ABS(Data!F46-Data!C9),ABS(Data!E46-Data!C9))=ABS(Data!F46-Data!C9),Data!F46,IF(MIN(ABS(Data!F46-Data!C9),ABS(Data!E46-Data!C9))=ABS(Data!E46-Data!C9),Data!E46,"")))) | F10: =IF(OR(C10="",D10=""),1,IF(ABS(D10-C10)>=3,0,IF(ABS(D10-C10)=2,0.5,IF(ABS(D10-C10)=1,0.75,1)))) -> 1 | G10: =IF(OR(C10="",E10=""),1,IF(ABS(E10-C10)>=3,0,IF(ABS(E10-C10)=2,0.5,IF(ABS(E10-C10)=1,0.75,1)))) -> 1 | H10: =IF(ISBLANK(Data!D9),"",Data!D9) | J10: =IF(ISBLANK(Data!F46),"",IF(Data!F46=Data!G46,Data!F46,IF(MIN(ABS(Data!F46-Data!E9),ABS(Data!G46-Data!E9))=ABS(Data!F46-Data!E9),Data!F46,IF(MIN(ABS(Data!F46-Data!E9),ABS(Data!G46-Data!E9))=ABS(Data!G46-Data!E9),Data!G46,"")))) | K10: =IF(OR(H10="",I10=""),1,IF(ABS(I10-H10)>=3,0,IF(ABS(I10-H10)=2,0.5,IF(ABS(I10-H10)=1,0.75,1)))) -> 1 | L10: =IF(OR(H10="",J10=""),1,IF(ABS(J10-H10)>=3,0,IF(ABS(J10-H10)=2,0.5,IF(ABS(J10-H10)=1,0.75,1)))) -> 1 | M10: =IF(ISBLANK(Data!E9),"",Data!E9) | N10: =IF(ISBLANK(Data!C47),"",IF(Data!C47=Data!D47,Data!C47,IF(MIN(ABS(Data!C47-Data!E9),ABS(Data!D47-Data!E9))=ABS(Data!C47-Data!E9),Data!C47,IF(MIN(ABS(Data!C47-Data!E9),ABS(Data!D47-Data!E9))=ABS(Data!D47-Data!E9),Data!D47,"")))) | O10: =IF(ISBLANK(Data!G46),"",IF(Data!G46=Data!F46,Data!G46,IF(MIN(ABS(Data!G46-Data!E9),ABS(Data!F46-Data!E9))=ABS(Data!G46-Data!E9),Data!G46,IF(MIN(ABS(Data!G46-Data!E9),ABS(Data!F46-Data!E9))=ABS(Data!F46-Data!E9),Data!F46,"")))) | P10: =IF(OR(M10="",N10=""),1,IF(ABS(N10-M10)>=3,0,IF(ABS(N10-M10)=2,0.5,IF(ABS(N10-M10)=1,0.75,1)))) -> 1 | Q10: =IF(OR(M10="",O10=""),1,IF(ABS(O10-M10)>=3,0,IF(ABS(O10-M10)=2,0.5,IF(ABS(O10-M10)=1,0.75,1)))) -> 1 | R10: =IF(ISBLANK(Data!F9),"",Data!F9) | S10: =IF(ISBLANK(Data!C47),"",IF(Data!C47=Data!D47,Data!C47,IF(MIN(ABS(Data!C47-Data!E9),ABS(Data!D47-Data!E9))=ABS(Data!C47-Data!E9),Data!C47,IF(MIN(ABS(Data!C47-Data!E9),ABS(Data!D47-Data!E9))=ABS(Data!D47-Data!E9),Data!D47,"")))) | T10: =IF(ISBLANK(Data!G46),"",IF(Data!G46=Data!G46,Data!G46,IF(MIN(ABS(Data!G46-Data!F9),ABS(Data!G46-Data!F9))=ABS(Data!G46-Data!F9),Data!G46,IF(MIN(ABS(Data!G46-Data!F9),ABS(Data!G46-Data!F9))=ABS(Data!G46-Data!F9),Data!G46,"")))) | U10: =IF(OR(R10="",S10=""),1,IF(ABS(S10-R10)>=3,0,IF(ABS(S10-R10)=2,0.5,IF(ABS(S10-R10)=1,0.75,1)))) -> 1 | V10: =IF(OR(R10="",T10=""),1,IF(ABS(T10-R10)>=3,0,IF(ABS(T10-R10)=2,0.5,IF(ABS(T10-R10)=1,0.75,1)))) -> 1 | W10: =AVERAGE(F10,K10,P10,U10) -> 1 | X10: =AVERAGE(G10,L10,Q10,V10) -> 1 | Y10: =+IF(W10>=0.8,1,IF(W10>=0.65,0.75,IF(W10>=0.5,0.5,IF(W10>=0.35,0.25,0)))) -> 1 | Z10: =+IF(X10>=0.8,1,IF(X10>=0.65,0.75,IF(X10>=0.5,0.5,IF(X10>=0.35,0.25,0)))) -> 1
B11: =B10+1 -> 5 | C11: =IF(ISBLANK(Data!C10),"",Data!C10) | E11: =IF(ISBLANK(Data!F47),"",IF(Data!F47=Data!E47,Data!F47,IF(MIN(ABS(Data!F47-Data!C10),ABS(Data!E47-Data!C10))=ABS(Data!F47-Data!C10),Data!F47,IF(MIN(ABS(Data!F47-Data!C10),ABS(Data!E47-Data!C10))=ABS(Data!E47-Data!C10),Data!E47,"")))) | F11: =IF(OR(C11="",D11=""),1,IF(ABS(D11-C11)>=3,0,IF(ABS(D11-C11)=2,0.5,IF(ABS(D11-C11)=1,0.75,1)))) -> 1 | G11: =IF(OR(C11="",E11=""),1,IF(ABS(E11-C11)>=3,0,IF(ABS(E11-C11)=2,0.5,IF(ABS(E11-C11)=1,0.75,1)))) -> 1 | H11: =IF(ISBLANK(Data!D10),"",Data!D10) | J11: =IF(ISBLANK(Data!F47),"",IF(Data!F47=Data!G47,Data!F47,IF(MIN(ABS(Data!F47-Data!E10),ABS(Data!G47-Data!E10))=ABS(Data!F47-Data!E10),Data!F47,IF(MIN(ABS(Data!F47-Data!E10),ABS(Data!G47-Data!E10))=ABS(Data!G47-Data!E10),Data!G47,"")))) | K11: =IF(OR(H11="",I11=""),1,IF(ABS(I11-H11)>=3,0,IF(ABS(I11-H11)=2,0.5,IF(ABS(I11-H11)=1,0.75,1)))) -> 1 | L11: =IF(OR(H11="",J11=""),1,IF(ABS(J11-H11)>=3,0,IF(ABS(J11-H11)=2,0.5,IF(ABS(J11-H11)=1,0.75,1)))) -> 1 | M11: =IF(ISBLANK(Data!E10),"",Data!E10) | N11: =IF(ISBLANK(Data!C48),"",IF(Data!C48=Data!D48,Data!C48,IF(MIN(ABS(Data!C48-Data!E10),ABS(Data!D48-Data!E10))=ABS(Data!C48-Data!E10),Data!C48,IF(MIN(ABS(Data!C48-Data!E10),ABS(Data!D48-Data!E10))=ABS(Data!D48-Data!E10),Data!D48,"")))) | O11: =IF(ISBLANK(Data!G47),"",IF(Data!G47=Data!F47,Data!G47,IF(MIN(ABS(Data!G47-Data!E10),ABS(Data!F47-Data!E10))=ABS(Data!G47-Data!E10),Data!G47,IF(MIN(ABS(Data!G47-Data!E10),ABS(Data!F47-Data!E10))=ABS(Data!F47-Data!E10),Data!F47,"")))) | P11: =IF(OR(M11="",N11=""),1,IF(ABS(N11-M11)>=3,0,IF(ABS(N11-M11)=2,0.5,IF(ABS(N11-M11)=1,0.75,1)))) -> 1 | Q11: =IF(OR(M11="",O11=""),1,IF(ABS(O11-M11)>=3,0,IF(ABS(O11-M11)=2,0.5,IF(ABS(O11-M11)=1,0.75,1)))) -> 1 | R11: =IF(ISBLANK(Data!F10),"",Data!F10) | S11: =IF(ISBLANK(Data!C48),"",IF(Data!C48=Data!D48,Data!C48,IF(MIN(ABS(Data!C48-Data!E10),ABS(Data!D48-Data!E10))=ABS(Data!C48-Data!E10),Data!C48,IF(MIN(ABS(Data!C48-Data!E10),ABS(Data!D48-Data!E10))=ABS(Data!D48-Data!E10),Data!D48,"")))) | T11: =IF(ISBLANK(Data!G47),"",IF(Data!G47=Data!G47,Data!G47,IF(MIN(ABS(Data!G47-Data!F10),ABS(Data!G47-Data!F10))=ABS(Data!G47-Data!F10),Data!G47,IF(MIN(ABS(Data!G47-Data!F10),ABS(Data!G47-Data!F10))=ABS(Data!G47-Data!F10),Data!G47,"")))) | U11: =IF(OR(R11="",S11=""),1,IF(ABS(S11-R11)>=3,0,IF(ABS(S11-R11)=2,0.5,IF(ABS(S11-R11)=1,0.75,1)))) -> 1 | V11: =IF(OR(R11="",T11=""),1,IF(ABS(T11-R11)>=3,0,IF(ABS(T11-R11)=2,0.5,IF(ABS(T11-R11)=1,0.75,1)))) -> 1 | W11: =AVERAGE(F11,K11,P11,U11) -> 1 | X11: =AVERAGE(G11,L11,Q11,V11) -> 1 | Y11: =+IF(W11>=0.8,1,IF(W11>=0.65,0.75,IF(W11>=0.5,0.5,IF(W11>=0.35,0.25,0)))) -> 1 | Z11: =+IF(X11>=0.8,1,IF(X11>=0.65,0.75,IF(X11>=0.5,0.5,IF(X11>=0.35,0.25,0)))) -> 1
B12: =B11+1 -> 6 | C12: =IF(ISBLANK(Data!C11),"",Data!C11) | E12: =IF(ISBLANK(Data!F48),"",IF(Data!F48=Data!E48,Data!F48,IF(MIN(ABS(Data!F48-Data!C11),ABS(Data!E48-Data!C11))=ABS(Data!F48-Data!C11),Data!F48,IF(MIN(ABS(Data!F48-Data!C11),ABS(Data!E48-Data!C11))=ABS(Data!E48-Data!C11),Data!E48,"")))) | F12: =IF(OR(C12="",D12=""),1,IF(ABS(D12-C12)>=3,0,IF(ABS(D12-C12)=2,0.5,IF(ABS(D12-C12)=1,0.75,1)))) -> 1 | G12: =IF(OR(C12="",E12=""),1,IF(ABS(E12-C12)>=3,0,IF(ABS(E12-C12)=2,0.5,IF(ABS(E12-C12)=1,0.75,1)))) -> 1 | H12: =IF(ISBLANK(Data!D11),"",Data!D11) | J12: =IF(ISBLANK(Data!F48),"",IF(Data!F48=Data!G48,Data!F48,IF(MIN(ABS(Data!F48-Data!E11),ABS(Data!G48-Data!E11))=ABS(Data!F48-Data!E11),Data!F48,IF(MIN(ABS(Data!F48-Data!E11),ABS(Data!G48-Data!E11))=ABS(Data!G48-Data!E11),Data!G48,"")))) | K12: =IF(OR(H12="",I12=""),1,IF(ABS(I12-H12)>=3,0,IF(ABS(I12-H12)=2,0.5,IF(ABS(I12-H12)=1,0.75,1)))) -> 1 | L12: =IF(OR(H12="",J12=""),1,IF(ABS(J12-H12)>=3,0,IF(ABS(J12-H12)=2,0.5,IF(ABS(J12-H12)=1,0.75,1)))) -> 1 | M12: =IF(ISBLANK(Data!E11),"",Data!E11) | N12: =IF(ISBLANK(Data!C49),"",IF(Data!C49=Data!D49,Data!C49,IF(MIN(ABS(Data!C49-Data!E11),ABS(Data!D49-Data!E11))=ABS(Data!C49-Data!E11),Data!C49,IF(MIN(ABS(Data!C49-Data!E11),ABS(Data!D49-Data!E11))=ABS(Data!D49-Data!E11),Data!D49,"")))) | O12: =IF(ISBLANK(Data!G48),"",IF(Data!G48=Data!F48,Data!G48,IF(MIN(ABS(Data!G48-Data!E11),ABS(Data!F48-Data!E11))=ABS(Data!G48-Data!E11),Data!G48,IF(MIN(ABS(Data!G48-Data!E11),ABS(Data!F48-Data!E11))=ABS(Data!F48-Data!E11),Data!F48,"")))) | P12: =IF(OR(M12="",N12=""),1,IF(ABS(N12-M12)>=3,0,IF(ABS(N12-M12)=2,0.5,IF(ABS(N12-M12)=1,0.75,1)))) -> 1 | Q12: =IF(OR(M12="",O12=""),1,IF(ABS(O12-M12)>=3,0,IF(ABS(O12-M12)=2,0.5,IF(ABS(O12-M12)=1,0.75,1)))) -> 1 | R12: =IF(ISBLANK(Data!F11),"",Data!F11) | S12: =IF(ISBLANK(Data!C49),"",IF(Data!C49=Data!D49,Data!C49,IF(MIN(ABS(Data!C49-Data!E11),ABS(Data!D49-Data!E11))=ABS(Data!C49-Data!E11),Data!C49,IF(MIN(ABS(Data!C49-Data!E11),ABS(Data!D49-Data!E11))=ABS(Data!D49-Data!E11),Data!D49,"")))) | T12: =IF(ISBLANK(Data!G48),"",IF(Data!G48=Data!G48,Data!G48,IF(MIN(ABS(Data!G48-Data!F11),ABS(Data!G48-Data!F11))=ABS(Data!G48-Data!F11),Data!G48,IF(MIN(ABS(Data!G48-Data!F11),ABS(Data!G48-Data!F11))=ABS(Data!G48-Data!F11),Data!G48,"")))) | U12: =IF(OR(R12="",S12=""),1,IF(ABS(S12-R12)>=3,0,IF(ABS(S12-R12)=2,0.5,IF(ABS(S12-R12)=1,0.75,1)))) -> 1 | V12: =IF(OR(R12="",T12=""),1,IF(ABS(T12-R12)>=3,0,IF(ABS(T12-R12)=2,0.5,IF(ABS(T12-R12)=1,0.75,1)))) -> 1 | W12: =AVERAGE(F12,K12,P12,U12) -> 1 | X12: =AVERAGE(G12,L12,Q12,V12) -> 1 | Y12: =+IF(W12>=0.8,1,IF(W12>=0.65,0.75,IF(W12>=0.5,0.5,IF(W12>=0.35,0.25,0)))) -> 1 | Z12: =+IF(X12>=0.8,1,IF(X12>=0.65,0.75,IF(X12>=0.5,0.5,IF(X12>=0.35,0.25,0)))) -> 1
B13: =B12+1 -> 7 | C13: =IF(ISBLANK(Data!C12),"",Data!C12) | E13: =IF(ISBLANK(Data!F49),"",IF(Data!F49=Data!E49,Data!F49,IF(MIN(ABS(Data!F49-Data!C12),ABS(Data!E49-Data!C12))=ABS(Data!F49-Data!C12),Data!F49,IF(MIN(ABS(Data!F49-Data!C12),ABS(Data!E49-Data!C12))=ABS(Data!E49-Data!C12),Data!E49,"")))) | F13: =IF(OR(C13="",D13=""),1,IF(ABS(D13-C13)>=3,0,IF(ABS(D13-C13)=2,0.5,IF(ABS(D13-C13)=1,0.75,1)))) -> 1 | G13: =IF(OR(C13="",E13=""),1,IF(ABS(E13-C13)>=3,0,IF(ABS(E13-C13)=2,0.5,IF(ABS(E13-C13)=1,0.75,1)))) -> 1 | H13: =IF(ISBLANK(Data!D12),"",Data!D12) | J13: =IF(ISBLANK(Data!F49),"",IF(Data!F49=Data!G49,Data!F49,IF(MIN(ABS(Data!F49-Data!E12),ABS(Data!G49-Data!E12))=ABS(Data!F49-Data!E12),Data!F49,IF(MIN(ABS(Data!F49-Data!E12),ABS(Data!G49-Data!E12))=ABS(Data!G49-Data!E12),Data!G49,"")))) | K13: =IF(OR(H13="",I13=""),1,IF(ABS(I13-H13)>=3,0,IF(ABS(I13-H13)=2,0.5,IF(ABS(I13-H13)=1,0.75,1)))) -> 1 | L13: =IF(OR(H13="",J13=""),1,IF(ABS(J13-H13)>=3,0,IF(ABS(J13-H13)=2,0.5,IF(ABS(J13-H13)=1,0.75,1)))) -> 1 | M13: =IF(ISBLANK(Data!E12),"",Data!E12) | N13: =IF(ISBLANK(Data!C50),"",IF(Data!C50=Data!D50,Data!C50,IF(MIN(ABS(Data!C50-Data!E12),ABS(Data!D50-Data!E12))=ABS(Data!C50-Data!E12),Data!C50,IF(MIN(ABS(Data!C50-Data!E12),ABS(Data!D50-Data!E12))=ABS(Data!D50-Data!E12),Data!D50,"")))) | O13: =IF(ISBLANK(Data!G49),"",IF(Data!G49=Data!F49,Data!G49,IF(MIN(ABS(Data!G49-Data!E12),ABS(Data!F49-Data!E12))=ABS(Data!G49-Data!E12),Data!G49,IF(MIN(ABS(Data!G49-Data!E12),ABS(Data!F49-Data!E12))=ABS(Data!F49-Data!E12),Data!F49,"")))) | P13: =IF(OR(M13="",N13=""),1,IF(ABS(N13-M13)>=3,0,IF(ABS(N13-M13)=2,0.5,IF(ABS(N13-M13)=1,0.75,1)))) -> 1 | Q13: =IF(OR(M13="",O13=""),1,IF(ABS(O13-M13)>=3,0,IF(ABS(O13-M13)=2,0.5,IF(ABS(O13-M13)=1,0.75,1)))) -> 1 | R13: =IF(ISBLANK(Data!F12),"",Data!F12) | S13: =IF(ISBLANK(Data!C50),"",IF(Data!C50=Data!D50,Data!C50,IF(MIN(ABS(Data!C50-Data!E12),ABS(Data!D50-Data!E12))=ABS(Data!C50-Data!E12),Data!C50,IF(MIN(ABS(Data!C50-Data!E12),ABS(Data!D50-Data!E12))=ABS(Data!D50-Data!E12),Data!D50,"")))) | T13: =IF(ISBLANK(Data!G49),"",IF(Data!G49=Data!G49,Data!G49,IF(MIN(ABS(Data!G49-Data!F12),ABS(Data!G49-Data!F12))=ABS(Data!G49-Data!F12),Data!G49,IF(MIN(ABS(Data!G49-Data!F12),ABS(Data!G49-Data!F12))=ABS(Data!G49-Data!F12),Data!G49,"")))) | U13: =IF(OR(R13="",S13=""),1,IF(ABS(S13-R13)>=3,0,IF(ABS(S13-R13)=2,0.5,IF(ABS(S13-R13)=1,0.75,1)))) -> 1 | V13: =IF(OR(R13="",T13=""),1,IF(ABS(T13-R13)>=3,0,IF(ABS(T13-R13)=2,0.5,IF(ABS(T13-R13)=1,0.75,1)))) -> 1 | W13: =AVERAGE(F13,K13,P13,U13) -> 1 | X13: =AVERAGE(G13,L13,Q13,V13) -> 1 | Y13: =+IF(W13>=0.8,1,IF(W13>=0.65,0.75,IF(W13>=0.5,0.5,IF(W13>=0.35,0.25,0)))) -> 1 | Z13: =+IF(X13>=0.8,1,IF(X13>=0.65,0.75,IF(X13>=0.5,0.5,IF(X13>=0.35,0.25,0)))) -> 1
B14: =B13+1 -> 8 | C14: =IF(ISBLANK(Data!C13),"",Data!C13) | E14: =IF(ISBLANK(Data!F50),"",IF(Data!F50=Data!E50,Data!F50,IF(MIN(ABS(Data!F50-Data!C13),ABS(Data!E50-Data!C13))=ABS(Data!F50-Data!C13),Data!F50,IF(MIN(ABS(Data!F50-Data!C13),ABS(Data!E50-Data!C13))=ABS(Data!E50-Data!C13),Data!E50,"")))) | F14: =IF(OR(C14="",D14=""),1,IF(ABS(D14-C14)>=3,0,IF(ABS(D14-C14)=2,0.5,IF(ABS(D14-C14)=1,0.75,1)))) -> 1 | G14: =IF(OR(C14="",E14=""),1,IF(ABS(E14-C14)>=3,0,IF(ABS(E14-C14)=2,0.5,IF(ABS(E14-C14)=1,0.75,1)))) -> 1 | H14: =IF(ISBLANK(Data!D13),"",Data!D13) | J14: =IF(ISBLANK(Data!F50),"",IF(Data!F50=Data!G50,Data!F50,IF(MIN(ABS(Data!F50-Data!E13),ABS(Data!G50-Data!E13))=ABS(Data!F50-Data!E13),Data!F50,IF(MIN(ABS(Data!F50-Data!E13),ABS(Data!G50-Data!E13))=ABS(Data!G50-Data!E13),Data!G50,"")))) | K14: =IF(OR(H14="",I14=""),1,IF(ABS(I14-H14)>=3,0,IF(ABS(I14-H14)=2,0.5,IF(ABS(I14-H14)=1,0.75,1)))) -> 1 | L14: =IF(OR(H14="",J14=""),1,IF(ABS(J14-H14)>=3,0,IF(ABS(J14-H14)=2,0.5,IF(ABS(J14-H14)=1,0.75,1)))) -> 1 | M14: =IF(ISBLANK(Data!E13),"",Data!E13) | N14: =IF(ISBLANK(Data!C51),"",IF(Data!C51=Data!D51,Data!C51,IF(MIN(ABS(Data!C51-Data!E13),ABS(Data!D51-Data!E13))=ABS(Data!C51-Data!E13),Data!C51,IF(MIN(ABS(Data!C51-Data!E13),ABS(Data!D51-Data!E13))=ABS(Data!D51-Data!E13),Data!D51,"")))) | O14: =IF(ISBLANK(Data!G50),"",IF(Data!G50=Data!F50,Data!G50,IF(MIN(ABS(Data!G50-Data!E13),ABS(Data!F50-Data!E13))=ABS(Data!G50-Data!E13),Data!G50,IF(MIN(ABS(Data!G50-Data!E13),ABS(Data!F50-Data!E13))=ABS(Data!F50-Data!E13),Data!F50,"")))) | P14: =IF(OR(M14="",N14=""),1,IF(ABS(N14-M14)>=3,0,IF(ABS(N14-M14)=2,0.5,IF(ABS(N14-M14)=1,0.75,1)))) -> 1 | Q14: =IF(OR(M14="",O14=""),1,IF(ABS(O14-M14)>=3,0,IF(ABS(O14-M14)=2,0.5,IF(ABS(O14-M14)=1,0.75,1)))) -> 1 | R14: =IF(ISBLANK(Data!F13),"",Data!F13) | S14: =IF(ISBLANK(Data!C51),"",IF(Data!C51=Data!D51,Data!C51,IF(MIN(ABS(Data!C51-Data!E13),ABS(Data!D51-Data!E13))=ABS(Data!C51-Data!E13),Data!C51,IF(MIN(ABS(Data!C51-Data!E13),ABS(Data!D51-Data!E13))=ABS(Data!D51-Data!E13),Data!D51,"")))) | T14: =IF(ISBLANK(Data!G50),"",IF(Data!G50=Data!G50,Data!G50,IF(MIN(ABS(Data!G50-Data!F13),ABS(Data!G50-Data!F13))=ABS(Data!G50-Data!F13),Data!G50,IF(MIN(ABS(Data!G50-Data!F13),ABS(Data!G50-Data!F13))=ABS(Data!G50-Data!F13),Data!G50,"")))) | U14: =IF(OR(R14="",S14=""),1,IF(ABS(S14-R14)>=3,0,IF(ABS(S14-R14)=2,0.5,IF(ABS(S14-R14)=1,0.75,1)))) -> 1 | V14: =IF(OR(R14="",T14=""),1,IF(ABS(T14-R14)>=3,0,IF(ABS(T14-R14)=2,0.5,IF(ABS(T14-R14)=1,0.75,1)))) -> 1 | W14: =AVERAGE(F14,K14,P14,U14) -> 1 | X14: =AVERAGE(G14,L14,Q14,V14) -> 1 | Y14: =+IF(W14>=0.8,1,IF(W14>=0.65,0.75,IF(W14>=0.5,0.5,IF(W14>=0.35,0.25,0)))) -> 1 | Z14: =+IF(X14>=0.8,1,IF(X14>=0.65,0.75,IF(X14>=0.5,0.5,IF(X14>=0.35,0.25,0)))) -> 1
B15: =B14+1 -> 9 | C15: =IF(ISBLANK(Data!C14),"",Data!C14) | E15: =IF(ISBLANK(Data!F51),"",IF(Data!F51=Data!E51,Data!F51,IF(MIN(ABS(Data!F51-Data!C14),ABS(Data!E51-Data!C14))=ABS(Data!F51-Data!C14),Data!F51,IF(MIN(ABS(Data!F51-Data!C14),ABS(Data!E51-Data!C14))=ABS(Data!E51-Data!C14),Data!E51,"")))) | F15: =IF(OR(C15="",D15=""),1,IF(ABS(D15-C15)>=3,0,IF(ABS(D15-C15)=2,0.5,IF(ABS(D15-C15)=1,0.75,1)))) -> 1 | G15: =IF(OR(C15="",E15=""),1,IF(ABS(E15-C15)>=3,0,IF(ABS(E15-C15)=2,0.5,IF(ABS(E15-C15)=1,0.75,1)))) -> 1 | H15: =IF(ISBLANK(Data!D14),"",Data!D14) | J15: =IF(ISBLANK(Data!F51),"",IF(Data!F51=Data!G51,Data!F51,IF(MIN(ABS(Data!F51-Data!E14),ABS(Data!G51-Data!E14))=ABS(Data!F51-Data!E14),Data!F51,IF(MIN(ABS(Data!F51-Data!E14),ABS(Data!G51-Data!E14))=ABS(Data!G51-Data!E14),Data!G51,"")))) | K15: =IF(OR(H15="",I15=""),1,IF(ABS(I15-H15)>=3,0,IF(ABS(I15-H15)=2,0.5,IF(ABS(I15-H15)=1,0.75,1)))) -> 1 | L15: =IF(OR(H15="",J15=""),1,IF(ABS(J15-H15)>=3,0,IF(ABS(J15-H15)=2,0.5,IF(ABS(J15-H15)=1,0.75,1)))) -> 1 | M15: =IF(ISBLANK(Data!E14),"",Data!E14) | N15: =IF(ISBLANK(Data!C52),"",IF(Data!C52=Data!D52,Data!C52,IF(MIN(ABS(Data!C52-Data!E14),ABS(Data!D52-Data!E14))=ABS(Data!C52-Data!E14),Data!C52,IF(MIN(ABS(Data!C52-Data!E14),ABS(Data!D52-Data!E14))=ABS(Data!D52-Data!E14),Data!D52,"")))) | O15: =IF(ISBLANK(Data!G51),"",IF(Data!G51=Data!F51,Data!G51,IF(MIN(ABS(Data!G51-Data!E14),ABS(Data!F51-Data!E14))=ABS(Data!G51-Data!E14),Data!G51,IF(MIN(ABS(Data!G51-Data!E14),ABS(Data!F51-Data!E14))=ABS(Data!F51-Data!E14),Data!F51,"")))) | P15: =IF(OR(M15="",N15=""),1,IF(ABS(N15-M15)>=3,0,IF(ABS(N15-M15)=2,0.5,IF(ABS(N15-M15)=1,0.75,1)))) -> 1 | Q15: =IF(OR(M15="",O15=""),1,IF(ABS(O15-M15)>=3,0,IF(ABS(O15-M15)=2,0.5,IF(ABS(O15-M15)=1,0.75,1)))) -> 1 | R15: =IF(ISBLANK(Data!F14),"",Data!F14) | S15: =IF(ISBLANK(Data!C52),"",IF(Data!C52=Data!D52,Data!C52,IF(MIN(ABS(Data!C52-Data!E14),ABS(Data!D52-Data!E14))=ABS(Data!C52-Data!E14),Data!C52,IF(MIN(ABS(Data!C52-Data!E14),ABS(Data!D52-Data!E14))=ABS(Data!D52-Data!E14),Data!D52,"")))) | T15: =IF(ISBLANK(Data!G51),"",IF(Data!G51=Data!G51,Data!G51,IF(MIN(ABS(Data!G51-Data!F14),ABS(Data!G51-Data!F14))=ABS(Data!G51-Data!F14),Data!G51,IF(MIN(ABS(Data!G51-Data!F14),ABS(Data!G51-Data!F14))=ABS(Data!G51-Data!F14),Data!G51,"")))) | U15: =IF(OR(R15="",S15=""),1,IF(ABS(S15-R15)>=3,0,IF(ABS(S15-R15)=2,0.5,IF(ABS(S15-R15)=1,0.75,1)))) -> 1 | V15: =IF(OR(R15="",T15=""),1,IF(ABS(T15-R15)>=3,0,IF(ABS(T15-R15)=2,0.5,IF(ABS(T15-R15)=1,0.75,1)))) -> 1 | W15: =AVERAGE(F15,K15,P15,U15) -> 1 | X15: =AVERAGE(G15,L15,Q15,V15) -> 1 | Y15: =+IF(W15>=0.8,1,IF(W15>=0.65,0.75,IF(W15>=0.5,0.5,IF(W15>=0.35,0.25,0)))) -> 1 | Z15: =+IF(X15>=0.8,1,IF(X15>=0.65,0.75,IF(X15>=0.5,0.5,IF(X15>=0.35,0.25,0)))) -> 1
B16: =B15+1 -> 10 | C16: =IF(ISBLANK(Data!C15),"",Data!C15) | E16: =IF(ISBLANK(Data!F52),"",IF(Data!F52=Data!E52,Data!F52,IF(MIN(ABS(Data!F52-Data!C15),ABS(Data!E52-Data!C15))=ABS(Data!F52-Data!C15),Data!F52,IF(MIN(ABS(Data!F52-Data!C15),ABS(Data!E52-Data!C15))=ABS(Data!E52-Data!C15),Data!E52,"")))) | F16: =IF(OR(C16="",D16=""),1,IF(ABS(D16-C16)>=3,0,IF(ABS(D16-C16)=2,0.5,IF(ABS(D16-C16)=1,0.75,1)))) -> 1 | G16: =IF(OR(C16="",E16=""),1,IF(ABS(E16-C16)>=3,0,IF(ABS(E16-C16)=2,0.5,IF(ABS(E16-C16)=1,0.75,1)))) -> 1 | H16: =IF(ISBLANK(Data!D15),"",Data!D15) | J16: =IF(ISBLANK(Data!F52),"",IF(Data!F52=Data!G52,Data!F52,IF(MIN(ABS(Data!F52-Data!E15),ABS(Data!G52-Data!E15))=ABS(Data!F52-Data!E15),Data!F52,IF(MIN(ABS(Data!F52-Data!E15),ABS(Data!G52-Data!E15))=ABS(Data!G52-Data!E15),Data!G52,"")))) | K16: =IF(OR(H16="",I16=""),1,IF(ABS(I16-H16)>=3,0,IF(ABS(I16-H16)=2,0.5,IF(ABS(I16-H16)=1,0.75,1)))) -> 1 | L16: =IF(OR(H16="",J16=""),1,IF(ABS(J16-H16)>=3,0,IF(ABS(J16-H16)=2,0.5,IF(ABS(J16-H16)=1,0.75,1)))) -> 1 | M16: =IF(ISBLANK(Data!E15),"",Data!E15) | N16: =IF(ISBLANK(Data!C53),"",IF(Data!C53=Data!D53,Data!C53,IF(MIN(ABS(Data!C53-Data!E15),ABS(Data!D53-Data!E15))=ABS(Data!C53-Data!E15),Data!C53,IF(MIN(ABS(Data!C53-Data!E15),ABS(Data!D53-Data!E15))=ABS(Data!D53-Data!E15),Data!D53,"")))) | O16: =IF(ISBLANK(Data!G52),"",IF(Data!G52=Data!F52,Data!G52,IF(MIN(ABS(Data!G52-Data!E15),ABS(Data!F52-Data!E15))=ABS(Data!G52-Data!E15),Data!G52,IF(MIN(ABS(Data!G52-Data!E15),ABS(Data!F52-Data!E15))=ABS(Data!F52-Data!E15),Data!F52,"")))) | P16: =IF(OR(M16="",N16=""),1,IF(ABS(N16-M16)>=3,0,IF(ABS(N16-M16)=2,0.5,IF(ABS(N16-M16)=1,0.75,1)))) -> 1 | Q16: =IF(OR(M16="",O16=""),1,IF(ABS(O16-M16)>=3,0,IF(ABS(O16-M16)=2,0.5,IF(ABS(O16-M16)=1,0.75,1)))) -> 1 | R16: =IF(ISBLANK(Data!F15),"",Data!F15) | S16: =IF(ISBLANK(Data!C53),"",IF(Data!C53=Data!D53,Data!C53,IF(MIN(ABS(Data!C53-Data!E15),ABS(Data!D53-Data!E15))=ABS(Data!C53-Data!E15),Data!C53,IF(MIN(ABS(Data!C53-Data!E15),ABS(Data!D53-Data!E15))=ABS(Data!D53-Data!E15),Data!D53,"")))) | T16: =IF(ISBLANK(Data!G52),"",IF(Data!G52=Data!G52,Data!G52,IF(MIN(ABS(Data!G52-Data!F15),ABS(Data!G52-Data!F15))=ABS(Data!G52-Data!F15),Data!G52,IF(MIN(ABS(Data!G52-Data!F15),ABS(Data!G52-Data!F15))=ABS(Data!G52-Data!F15),Data!G52,"")))) | U16: =IF(OR(R16="",S16=""),1,IF(ABS(S16-R16)>=3,0,IF(ABS(S16-R16)=2,0.5,IF(ABS(S16-R16)=1,0.75,1)))) -> 1 | V16: =IF(OR(R16="",T16=""),1,IF(ABS(T16-R16)>=3,0,IF(ABS(T16-R16)=2,0.5,IF(ABS(T16-R16)=1,0.75,1)))) -> 1 | W16: =AVERAGE(F16,K16,P16,U16) -> 1 | X16: =AVERAGE(G16,L16,Q16,V16) -> 1 | Y16: =+IF(W16>=0.8,1,IF(W16>=0.65,0.75,IF(W16>=0.5,0.5,IF(W16>=0.35,0.25,0)))) -> 1 | Z16: =+IF(X16>=0.8,1,IF(X16>=0.65,0.75,IF(X16>=0.5,0.5,IF(X16>=0.35,0.25,0)))) -> 1 | AB16: =IF(ISBLANK(Data!C44),"",IF(Data!C44=Data!D44,Data!C44,IF(MIN(ABS(Data!C44-Data!E6),ABS(Data!D44-Data!E6))=ABS(Data!C44-Data!E6),Data!C44,IF(MIN(ABS(Data!C44-Data!E6),ABS(Data!D44-Data!E6))=ABS(Data!D44-Data!E6),Data!D44,""))))
B17: =B16+1 -> 11 | C17: =IF(ISBLANK(Data!C16),"",Data!C16) | E17: =IF(ISBLANK(Data!F53),"",IF(Data!F53=Data!E53,Data!F53,IF(MIN(ABS(Data!F53-Data!C16),ABS(Data!E53-Data!C16))=ABS(Data!F53-Data!C16),Data!F53,IF(MIN(ABS(Data!F53-Data!C16),ABS(Data!E53-Data!C16))=ABS(Data!E53-Data!C16),Data!E53,"")))) | F17: =IF(OR(C17="",D17=""),1,IF(ABS(D17-C17)>=3,0,IF(ABS(D17-C17)=2,0.5,IF(ABS(D17-C17)=1,0.75,1)))) -> 1 | G17: =IF(OR(C17="",E17=""),1,IF(ABS(E17-C17)>=3,0,IF(ABS(E17-C17)=2,0.5,IF(ABS(E17-C17)=1,0.75,1)))) -> 1 | H17: =IF(ISBLANK(Data!D16),"",Data!D16) | J17: =IF(ISBLANK(Data!F53),"",IF(Data!F53=Data!G53,Data!F53,IF(MIN(ABS(Data!F53-Data!E16),ABS(Data!G53-Data!E16))=ABS(Data!F53-Data!E16),Data!F53,IF(MIN(ABS(Data!F53-Data!E16),ABS(Data!G53-Data!E16))=ABS(Data!G53-Data!E16),Data!G53,"")))) | K17: =IF(OR(H17="",I17=""),1,IF(ABS(I17-H17)>=3,0,IF(ABS(I17-H17)=2,0.5,IF(ABS(I17-H17)=1,0.75,1)))) -> 1 | L17: =IF(OR(H17="",J17=""),1,IF(ABS(J17-H17)>=3,0,IF(ABS(J17-H17)=2,0.5,IF(ABS(J17-H17)=1,0.75,1)))) -> 1 | M17: =IF(ISBLANK(Data!E16),"",Data!E16) | N17: =IF(ISBLANK(Data!C54),"",IF(Data!C54=Data!D54,Data!C54,IF(MIN(ABS(Data!C54-Data!E16),ABS(Data!D54-Data!E16))=ABS(Data!C54-Data!E16),Data!C54,IF(MIN(ABS(Data!C54-Data!E16),ABS(Data!D54-Data!E16))=ABS(Data!D54-Data!E16),Data!D54,"")))) | O17: =IF(ISBLANK(Data!G53),"",IF(Data!G53=Data!F53,Data!G53,IF(MIN(ABS(Data!G53-Data!E16),ABS(Data!F53-Data!E16))=ABS(Data!G53-Data!E16),Data!G53,IF(MIN(ABS(Data!G53-Data!E16),ABS(Data!F53-Data!E16))=ABS(Data!F53-Data!E16),Data!F53,"")))) | P17: =IF(OR(M17="",N17=""),1,IF(ABS(N17-M17)>=3,0,IF(ABS(N17-M17)=2,0.5,IF(ABS(N17-M17)=1,0.75,1)))) -> 1 | Q17: =IF(OR(M17="",O17=""),1,IF(ABS(O17-M17)>=3,0,IF(ABS(O17-M17)=2,0.5,IF(ABS(O17-M17)=1,0.75,1)))) -> 1 | R17: =IF(ISBLANK(Data!F16),"",Data!F16) | S17: =IF(ISBLANK(Data!C54),"",IF(Data!C54=Data!D54,Data!C54,IF(MIN(ABS(Data!C54-Data!E16),ABS(Data!D54-Data!E16))=ABS(Data!C54-Data!E16),Data!C54,IF(MIN(ABS(Data!C54-Data!E16),ABS(Data!D54-Data!E16))=ABS(Data!D54-Data!E16),Data!D54,"")))) | T17: =IF(ISBLANK(Data!G53),"",IF(Data!G53=Data!G53,Data!G53,IF(MIN(ABS(Data!G53-Data!F16),ABS(Data!G53-Data!F16))=ABS(Data!G53-Data!F16),Data!G53,IF(MIN(ABS(Data!G53-Data!F16),ABS(Data!G53-Data!F16))=ABS(Data!G53-Data!F16),Data!G53,"")))) | U17: =IF(OR(R17="",S17=""),1,IF(ABS(S17-R17)>=3,0,IF(ABS(S17-R17)=2,0.5,IF(ABS(S17-R17)=1,0.75,1)))) -> 1 | V17: =IF(OR(R17="",T17=""),1,IF(ABS(T17-R17)>=3,0,IF(ABS(T17-R17)=2,0.5,IF(ABS(T17-R17)=1,0.75,1)))) -> 1 | W17: =AVERAGE(F17,K17,P17,U17) -> 1 | X17: =AVERAGE(G17,L17,Q17,V17) -> 1 | Y17: =+IF(W17>=0.8,1,IF(W17>=0.65,0.75,IF(W17>=0.5,0.5,IF(W17>=0.35,0.25,0)))) -> 1 | Z17: =+IF(X17>=0.8,1,IF(X17>=0.65,0.75,IF(X17>=0.5,0.5,IF(X17>=0.35,0.25,0)))) -> 1
B18: =B17+1 -> 12 | C18: =IF(ISBLANK(Data!C17),"",Data!C17) | E18: =IF(ISBLANK(Data!F54),"",IF(Data!F54=Data!E54,Data!F54,IF(MIN(ABS(Data!F54-Data!C17),ABS(Data!E54-Data!C17))=ABS(Data!F54-Data!C17),Data!F54,IF(MIN(ABS(Data!F54-Data!C17),ABS(Data!E54-Data!C17))=ABS(Data!E54-Data!C17),Data!E54,"")))) | F18: =IF(OR(C18="",D18=""),1,IF(ABS(D18-C18)>=3,0,IF(ABS(D18-C18)=2,0.5,IF(ABS(D18-C18)=1,0.75,1)))) -> 1 | G18: =IF(OR(C18="",E18=""),1,IF(ABS(E18-C18)>=3,0,IF(ABS(E18-C18)=2,0.5,IF(ABS(E18-C18)=1,0.75,1)))) -> 1 | H18: =IF(ISBLANK(Data!D17),"",Data!D17) | J18: =IF(ISBLANK(Data!F54),"",IF(Data!F54=Data!G54,Data!F54,IF(MIN(ABS(Data!F54-Data!E17),ABS(Data!G54-Data!E17))=ABS(Data!F54-Data!E17),Data!F54,IF(MIN(ABS(Data!F54-Data!E17),ABS(Data!G54-Data!E17))=ABS(Data!G54-Data!E17),Data!G54,"")))) | K18: =IF(OR(H18="",I18=""),1,IF(ABS(I18-H18)>=3,0,IF(ABS(I18-H18)=2,0.5,IF(ABS(I18-H18)=1,0.75,1)))) -> 1 | L18: =IF(OR(H18="",J18=""),1,IF(ABS(J18-H18)>=3,0,IF(ABS(J18-H18)=2,0.5,IF(ABS(J18-H18)=1,0.75,1)))) -> 1 | M18: =IF(ISBLANK(Data!E17),"",Data!E17) | N18: =IF(ISBLANK(Data!C55),"",IF(Data!C55=Data!D55,Data!C55,IF(MIN(ABS(Data!C55-Data!E17),ABS(Data!D55-Data!E17))=ABS(Data!C55-Data!E17),Data!C55,IF(MIN(ABS(Data!C55-Data!E17),ABS(Data!D55-Data!E17))=ABS(Data!D55-Data!E17),Data!D55,"")))) | O18: =IF(ISBLANK(Data!G54),"",IF(Data!G54=Data!F54,Data!G54,IF(MIN(ABS(Data!G54-Data!E17),ABS(Data!F54-Data!E17))=ABS(Data!G54-Data!E17),Data!G54,IF(MIN(ABS(Data!G54-Data!E17),ABS(Data!F54-Data!E17))=ABS(Data!F54-Data!E17),Data!F54,"")))) | P18: =IF(OR(M18="",N18=""),1,IF(ABS(N18-M18)>=3,0,IF(ABS(N18-M18)=2,0.5,IF(ABS(N18-M18)=1,0.75,1)))) -> 1 | Q18: =IF(OR(M18="",O18=""),1,IF(ABS(O18-M18)>=3,0,IF(ABS(O18-M18)=2,0.5,IF(ABS(O18-M18)=1,0.75,1)))) -> 1 | R18: =IF(ISBLANK(Data!F17),"",Data!F17) | S18: =IF(ISBLANK(Data!C55),"",IF(Data!C55=Data!D55,Data!C55,IF(MIN(ABS(Data!C55-Data!E17),ABS(Data!D55-Data!E17))=ABS(Data!C55-Data!E17),Data!C55,IF(MIN(ABS(Data!C55-Data!E17),ABS(Data!D55-Data!E17))=ABS(Data!D55-Data!E17),Data!D55,"")))) | T18: =IF(ISBLANK(Data!G54),"",IF(Data!G54=Data!G54,Data!G54,IF(MIN(ABS(Data!G54-Data!F17),ABS(Data!G54-Data!F17))=ABS(Data!G54-Data!F17),Data!G54,IF(MIN(ABS(Data!G54-Data!F17),ABS(Data!G54-Data!F17))=ABS(Data!G54-Data!F17),Data!G54,"")))) | U18: =IF(OR(R18="",S18=""),1,IF(ABS(S18-R18)>=3,0,IF(ABS(S18-R18)=2,0.5,IF(ABS(S18-R18)=1,0.75,1)))) -> 1 | V18: =IF(OR(R18="",T18=""),1,IF(ABS(T18-R18)>=3,0,IF(ABS(T18-R18)=2,0.5,IF(ABS(T18-R18)=1,0.75,1)))) -> 1 | W18: =AVERAGE(F18,K18,P18,U18) -> 1 | X18: =AVERAGE(G18,L18,Q18,V18) -> 1 | Y18: =+IF(W18>=0.8,1,IF(W18>=0.65,0.75,IF(W18>=0.5,0.5,IF(W18>=0.35,0.25,0)))) -> 1 | Z18: =+IF(X18>=0.8,1,IF(X18>=0.65,0.75,IF(X18>=0.5,0.5,IF(X18>=0.35,0.25,0)))) -> 1
B19: =B18+1 -> 13 | C19: =IF(ISBLANK(Data!C18),"",Data!C18) | E19: =IF(ISBLANK(Data!F55),"",IF(Data!F55=Data!E55,Data!F55,IF(MIN(ABS(Data!F55-Data!C18),ABS(Data!E55-Data!C18))=ABS(Data!F55-Data!C18),Data!F55,IF(MIN(ABS(Data!F55-Data!C18),ABS(Data!E55-Data!C18))=ABS(Data!E55-Data!C18),Data!E55,"")))) | F19: =IF(OR(C19="",D19=""),1,IF(ABS(D19-C19)>=3,0,IF(ABS(D19-C19)=2,0.5,IF(ABS(D19-C19)=1,0.75,1)))) -> 1 | G19: =IF(OR(C19="",E19=""),1,IF(ABS(E19-C19)>=3,0,IF(ABS(E19-C19)=2,0.5,IF(ABS(E19-C19)=1,0.75,1)))) -> 1 | H19: =IF(ISBLANK(Data!D18),"",Data!D18) | J19: =IF(ISBLANK(Data!F55),"",IF(Data!F55=Data!G55,Data!F55,IF(MIN(ABS(Data!F55-Data!E18),ABS(Data!G55-Data!E18))=ABS(Data!F55-Data!E18),Data!F55,IF(MIN(ABS(Data!F55-Data!E18),ABS(Data!G55-Data!E18))=ABS(Data!G55-Data!E18),Data!G55,"")))) | K19: =IF(OR(H19="",I19=""),1,IF(ABS(I19-H19)>=3,0,IF(ABS(I19-H19)=2,0.5,IF(ABS(I19-H19)=1,0.75,1)))) -> 1 | L19: =IF(OR(H19="",J19=""),1,IF(ABS(J19-H19)>=3,0,IF(ABS(J19-H19)=2,0.5,IF(ABS(J19-H19)=1,0.75,1)))) -> 1 | M19: =IF(ISBLANK(Data!E18),"",Data!E18) | N19: =IF(ISBLANK(Data!C56),"",IF(Data!C56=Data!D56,Data!C56,IF(MIN(ABS(Data!C56-Data!E18),ABS(Data!D56-Data!E18))=ABS(Data!C56-Data!E18),Data!C56,IF(MIN(ABS(Data!C56-Data!E18),ABS(Data!D56-Data!E18))=ABS(Data!D56-Data!E18),Data!D56,"")))) | O19: =IF(ISBLANK(Data!G55),"",IF(Data!G55=Data!F55,Data!G55,IF(MIN(ABS(Data!G55-Data!E18),ABS(Data!F55-Data!E18))=ABS(Data!G55-Data!E18),Data!G55,IF(MIN(ABS(Data!G55-Data!E18),ABS(Data!F55-Data!E18))=ABS(Data!F55-Data!E18),Data!F55,"")))) | P19: =IF(OR(M19="",N19=""),1,IF(ABS(N19-M19)>=3,0,IF(ABS(N19-M19)=2,0.5,IF(ABS(N19-M19)=1,0.75,1)))) -> 1 | Q19: =IF(OR(M19="",O19=""),1,IF(ABS(O19-M19)>=3,0,IF(ABS(O19-M19)=2,0.5,IF(ABS(O19-M19)=1,0.75,1)))) -> 1 | R19: =IF(ISBLANK(Data!F18),"",Data!F18) | S19: =IF(ISBLANK(Data!C56),"",IF(Data!C56=Data!D56,Data!C56,IF(MIN(ABS(Data!C56-Data!E18),ABS(Data!D56-Data!E18))=ABS(Data!C56-Data!E18),Data!C56,IF(MIN(ABS(Data!C56-Data!E18),ABS(Data!D56-Data!E18))=ABS(Data!D56-Data!E18),Data!D56,"")))) | T19: =IF(ISBLANK(Data!G55),"",IF(Data!G55=Data!G55,Data!G55,IF(MIN(ABS(Data!G55-Data!F18),ABS(Data!G55-Data!F18))=ABS(Data!G55-Data!F18),Data!G55,IF(MIN(ABS(Data!G55-Data!F18),ABS(Data!G55-Data!F18))=ABS(Data!G55-Data!F18),Data!G55,"")))) | U19: =IF(OR(R19="",S19=""),1,IF(ABS(S19-R19)>=3,0,IF(ABS(S19-R19)=2,0.5,IF(ABS(S19-R19)=1,0.75,1)))) -> 1 | V19: =IF(OR(R19="",T19=""),1,IF(ABS(T19-R19)>=3,0,IF(ABS(T19-R19)=2,0.5,IF(ABS(T19-R19)=1,0.75,1)))) -> 1 | W19: =AVERAGE(F19,K19,P19,U19) -> 1 | X19: =AVERAGE(G19,L19,Q19,V19) -> 1 | Y19: =+IF(W19>=0.8,1,IF(W19>=0.65,0.75,IF(W19>=0.5,0.5,IF(W19>=0.35,0.25,0)))) -> 1 | Z19: =+IF(X19>=0.8,1,IF(X19>=0.65,0.75,IF(X19>=0.5,0.5,IF(X19>=0.35,0.25,0)))) -> 1
B20: =B19+1 -> 14 | C20: =IF(ISBLANK(Data!C19),"",Data!C19) | E20: =IF(ISBLANK(Data!F56),"",IF(Data!F56=Data!E56,Data!F56,IF(MIN(ABS(Data!F56-Data!C19),ABS(Data!E56-Data!C19))=ABS(Data!F56-Data!C19),Data!F56,IF(MIN(ABS(Data!F56-Data!C19),ABS(Data!E56-Data!C19))=ABS(Data!E56-Data!C19),Data!E56,"")))) | F20: =IF(OR(C20="",D20=""),1,IF(ABS(D20-C20)>=3,0,IF(ABS(D20-C20)=2,0.5,IF(ABS(D20-C20)=1,0.75,1)))) -> 1 | G20: =IF(OR(C20="",E20=""),1,IF(ABS(E20-C20)>=3,0,IF(ABS(E20-C20)=2,0.5,IF(ABS(E20-C20)=1,0.75,1)))) -> 1 | H20: =IF(ISBLANK(Data!D19),"",Data!D19) | J20: =IF(ISBLANK(Data!F56),"",IF(Data!F56=Data!G56,Data!F56,IF(MIN(ABS(Data!F56-Data!E19),ABS(Data!G56-Data!E19))=ABS(Data!F56-Data!E19),Data!F56,IF(MIN(ABS(Data!F56-Data!E19),ABS(Data!G56-Data!E19))=ABS(Data!G56-Data!E19),Data!G56,"")))) | K20: =IF(OR(H20="",I20=""),1,IF(ABS(I20-H20)>=3,0,IF(ABS(I20-H20)=2,0.5,IF(ABS(I20-H20)=1,0.75,1)))) -> 1 | L20: =IF(OR(H20="",J20=""),1,IF(ABS(J20-H20)>=3,0,IF(ABS(J20-H20)=2,0.5,IF(ABS(J20-H20)=1,0.75,1)))) -> 1 | M20: =IF(ISBLANK(Data!E19),"",Data!E19) | N20: =IF(ISBLANK(Data!C57),"",IF(Data!C57=Data!D57,Data!C57,IF(MIN(ABS(Data!C57-Data!E19),ABS(Data!D57-Data!E19))=ABS(Data!C57-Data!E19),Data!C57,IF(MIN(ABS(Data!C57-Data!E19),ABS(Data!D57-Data!E19))=ABS(Data!D57-Data!E19),Data!D57,"")))) | O20: =IF(ISBLANK(Data!G56),"",IF(Data!G56=Data!F56,Data!G56,IF(MIN(ABS(Data!G56-Data!E19),ABS(Data!F56-Data!E19))=ABS(Data!G56-Data!E19),Data!G56,IF(MIN(ABS(Data!G56-Data!E19),ABS(Data!F56-Data!E19))=ABS(Data!F56-Data!E19),Data!F56,"")))) | P20: =IF(OR(M20="",N20=""),1,IF(ABS(N20-M20)>=3,0,IF(ABS(N20-M20)=2,0.5,IF(ABS(N20-M20)=1,0.75,1)))) -> 1 | Q20: =IF(OR(M20="",O20=""),1,IF(ABS(O20-M20)>=3,0,IF(ABS(O20-M20)=2,0.5,IF(ABS(O20-M20)=1,0.75,1)))) -> 1 | R20: =IF(ISBLANK(Data!F19),"",Data!F19) | S20: =IF(ISBLANK(Data!C57),"",IF(Data!C57=Data!D57,Data!C57,IF(MIN(ABS(Data!C57-Data!E19),ABS(Data!D57-Data!E19))=ABS(Data!C57-Data!E19),Data!C57,IF(MIN(ABS(Data!C57-Data!E19),ABS(Data!D57-Data!E19))=ABS(Data!D57-Data!E19),Data!D57,"")))) | T20: =IF(ISBLANK(Data!G56),"",IF(Data!G56=Data!G56,Data!G56,IF(MIN(ABS(Data!G56-Data!F19),ABS(Data!G56-Data!F19))=ABS(Data!G56-Data!F19),Data!G56,IF(MIN(ABS(Data!G56-Data!F19),ABS(Data!G56-Data!F19))=ABS(Data!G56-Data!F19),Data!G56,"")))) | U20: =IF(OR(R20="",S20=""),1,IF(ABS(S20-R20)>=3,0,IF(ABS(S20-R20)=2,0.5,IF(ABS(S20-R20)=1,0.75,1)))) -> 1 | V20: =IF(OR(R20="",T20=""),1,IF(ABS(T20-R20)>=3,0,IF(ABS(T20-R20)=2,0.5,IF(ABS(T20-R20)=1,0.75,1)))) -> 1 | W20: =AVERAGE(F20,K20,P20,U20) -> 1 | X20: =AVERAGE(G20,L20,Q20,V20) -> 1 | Y20: =+IF(W20>=0.8,1,IF(W20>=0.65,0.75,IF(W20>=0.5,0.5,IF(W20>=0.35,0.25,0)))) -> 1 | Z20: =+IF(X20>=0.8,1,IF(X20>=0.65,0.75,IF(X20>=0.5,0.5,IF(X20>=0.35,0.25,0)))) -> 1
B21: =B20+1 -> 15 | C21: =IF(ISBLANK(Data!C20),"",Data!C20) | E21: =IF(ISBLANK(Data!F57),"",IF(Data!F57=Data!E57,Data!F57,IF(MIN(ABS(Data!F57-Data!C20),ABS(Data!E57-Data!C20))=ABS(Data!F57-Data!C20),Data!F57,IF(MIN(ABS(Data!F57-Data!C20),ABS(Data!E57-Data!C20))=ABS(Data!E57-Data!C20),Data!E57,"")))) | F21: =IF(OR(C21="",D21=""),1,IF(ABS(D21-C21)>=3,0,IF(ABS(D21-C21)=2,0.5,IF(ABS(D21-C21)=1,0.75,1)))) -> 1 | G21: =IF(OR(C21="",E21=""),1,IF(ABS(E21-C21)>=3,0,IF(ABS(E21-C21)=2,0.5,IF(ABS(E21-C21)=1,0.75,1)))) -> 1 | H21: =IF(ISBLANK(Data!D20),"",Data!D20) | J21: =IF(ISBLANK(Data!F57),"",IF(Data!F57=Data!G57,Data!F57,IF(MIN(ABS(Data!F57-Data!E20),ABS(Data!G57-Data!E20))=ABS(Data!F57-Data!E20),Data!F57,IF(MIN(ABS(Data!F57-Data!E20),ABS(Data!G57-Data!E20))=ABS(Data!G57-Data!E20),Data!G57,"")))) | K21: =IF(OR(H21="",I21=""),1,IF(ABS(I21-H21)>=3,0,IF(ABS(I21-H21)=2,0.5,IF(ABS(I21-H21)=1,0.75,1)))) -> 1 | L21: =IF(OR(H21="",J21=""),1,IF(ABS(J21-H21)>=3,0,IF(ABS(J21-H21)=2,0.5,IF(ABS(J21-H21)=1,0.75,1)))) -> 1 | M21: =IF(ISBLANK(Data!E20),"",Data!E20) | N21: =IF(ISBLANK(Data!C58),"",IF(Data!C58=Data!D58,Data!C58,IF(MIN(ABS(Data!C58-Data!E20),ABS(Data!D58-Data!E20))=ABS(Data!C58-Data!E20),Data!C58,IF(MIN(ABS(Data!C58-Data!E20),ABS(Data!D58-Data!E20))=ABS(Data!D58-Data!E20),Data!D58,"")))) | O21: =IF(ISBLANK(Data!G57),"",IF(Data!G57=Data!F57,Data!G57,IF(MIN(ABS(Data!G57-Data!E20),ABS(Data!F57-Data!E20))=ABS(Data!G57-Data!E20),Data!G57,IF(MIN(ABS(Data!G57-Data!E20),ABS(Data!F57-Data!E20))=ABS(Data!F57-Data!E20),Data!F57,"")))) | P21: =IF(OR(M21="",N21=""),1,IF(ABS(N21-M21)>=3,0,IF(ABS(N21-M21)=2,0.5,IF(ABS(N21-M21)=1,0.75,1)))) -> 1 | Q21: =IF(OR(M21="",O21=""),1,IF(ABS(O21-M21)>=3,0,IF(ABS(O21-M21)=2,0.5,IF(ABS(O21-M21)=1,0.75,1)))) -> 1 | R21: =IF(ISBLANK(Data!F20),"",Data!F20) | S21: =IF(ISBLANK(Data!C58),"",IF(Data!C58=Data!D58,Data!C58,IF(MIN(ABS(Data!C58-Data!E20),ABS(Data!D58-Data!E20))=ABS(Data!C58-Data!E20),Data!C58,IF(MIN(ABS(Data!C58-Data!E20),ABS(Data!D58-Data!E20))=ABS(Data!D58-Data!E20),Data!D58,"")))) | T21: =IF(ISBLANK(Data!G57),"",IF(Data!G57=Data!G57,Data!G57,IF(MIN(ABS(Data!G57-Data!F20),ABS(Data!G57-Data!F20))=ABS(Data!G57-Data!F20),Data!G57,IF(MIN(ABS(Data!G57-Data!F20),ABS(Data!G57-Data!F20))=ABS(Data!G57-Data!F20),Data!G57,"")))) | U21: =IF(OR(R21="",S21=""),1,IF(ABS(S21-R21)>=3,0,IF(ABS(S21-R21)=2,0.5,IF(ABS(S21-R21)=1,0.75,1)))) -> 1 | V21: =IF(OR(R21="",T21=""),1,IF(ABS(T21-R21)>=3,0,IF(ABS(T21-R21)=2,0.5,IF(ABS(T21-R21)=1,0.75,1)))) -> 1 | W21: =AVERAGE(F21,K21,P21,U21) -> 1 | X21: =AVERAGE(G21,L21,Q21,V21) -> 1 | Y21: =+IF(W21>=0.8,1,IF(W21>=0.65,0.75,IF(W21>=0.5,0.5,IF(W21>=0.35,0.25,0)))) -> 1 | Z21: =+IF(X21>=0.8,1,IF(X21>=0.65,0.75,IF(X21>=0.5,0.5,IF(X21>=0.35,0.25,0)))) -> 1
B22: =B21+1 -> 16 | C22: =IF(ISBLANK(Data!C21),"",Data!C21) | E22: =IF(ISBLANK(Data!F58),"",IF(Data!F58=Data!E58,Data!F58,IF(MIN(ABS(Data!F58-Data!C21),ABS(Data!E58-Data!C21))=ABS(Data!F58-Data!C21),Data!F58,IF(MIN(ABS(Data!F58-Data!C21),ABS(Data!E58-Data!C21))=ABS(Data!E58-Data!C21),Data!E58,"")))) | F22: =IF(OR(C22="",D22=""),1,IF(ABS(D22-C22)>=3,0,IF(ABS(D22-C22)=2,0.5,IF(ABS(D22-C22)=1,0.75,1)))) -> 1 | G22: =IF(OR(C22="",E22=""),1,IF(ABS(E22-C22)>=3,0,IF(ABS(E22-C22)=2,0.5,IF(ABS(E22-C22)=1,0.75,1)))) -> 1 | H22: =IF(ISBLANK(Data!D21),"",Data!D21) | J22: =IF(ISBLANK(Data!F58),"",IF(Data!F58=Data!G58,Data!F58,IF(MIN(ABS(Data!F58-Data!E21),ABS(Data!G58-Data!E21))=ABS(Data!F58-Data!E21),Data!F58,IF(MIN(ABS(Data!F58-Data!E21),ABS(Data!G58-Data!E21))=ABS(Data!G58-Data!E21),Data!G58,"")))) | K22: =IF(OR(H22="",I22=""),1,IF(ABS(I22-H22)>=3,0,IF(ABS(I22-H22)=2,0.5,IF(ABS(I22-H22)=1,0.75,1)))) -> 1 | L22: =IF(OR(H22="",J22=""),1,IF(ABS(J22-H22)>=3,0,IF(ABS(J22-H22)=2,0.5,IF(ABS(J22-H22)=1,0.75,1)))) -> 1 | M22: =IF(ISBLANK(Data!E21),"",Data!E21) | N22: =IF(ISBLANK(Data!C59),"",IF(Data!C59=Data!D59,Data!C59,IF(MIN(ABS(Data!C59-Data!E21),ABS(Data!D59-Data!E21))=ABS(Data!C59-Data!E21),Data!C59,IF(MIN(ABS(Data!C59-Data!E21),ABS(Data!D59-Data!E21))=ABS(Data!D59-Data!E21),Data!D59,"")))) | O22: =IF(ISBLANK(Data!G58),"",IF(Data!G58=Data!F58,Data!G58,IF(MIN(ABS(Data!G58-Data!E21),ABS(Data!F58-Data!E21))=ABS(Data!G58-Data!E21),Data!G58,IF(MIN(ABS(Data!G58-Data!E21),ABS(Data!F58-Data!E21))=ABS(Data!F58-Data!E21),Data!F58,"")))) | P22: =IF(OR(M22="",N22=""),1,IF(ABS(N22-M22)>=3,0,IF(ABS(N22-M22)=2,0.5,IF(ABS(N22-M22)=1,0.75,1)))) -> 1 | Q22: =IF(OR(M22="",O22=""),1,IF(ABS(O22-M22)>=3,0,IF(ABS(O22-M22)=2,0.5,IF(ABS(O22-M22)=1,0.75,1)))) -> 1 | R22: =IF(ISBLANK(Data!F21),"",Data!F21) | S22: =IF(ISBLANK(Data!C59),"",IF(Data!C59=Data!D59,Data!C59,IF(MIN(ABS(Data!C59-Data!E21),ABS(Data!D59-Data!E21))=ABS(Data!C59-Data!E21),Data!C59,IF(MIN(ABS(Data!C59-Data!E21),ABS(Data!D59-Data!E21))=ABS(Data!D59-Data!E21),Data!D59,"")))) | T22: =IF(ISBLANK(Data!G58),"",IF(Data!G58=Data!G58,Data!G58,IF(MIN(ABS(Data!G58-Data!F21),ABS(Data!G58-Data!F21))=ABS(Data!G58-Data!F21),Data!G58,IF(MIN(ABS(Data!G58-Data!F21),ABS(Data!G58-Data!F21))=ABS(Data!G58-Data!F21),Data!G58,"")))) | U22: =IF(OR(R22="",S22=""),1,IF(ABS(S22-R22)>=3,0,IF(ABS(S22-R22)=2,0.5,IF(ABS(S22-R22)=1,0.75,1)))) -> 1 | V22: =IF(OR(R22="",T22=""),1,IF(ABS(T22-R22)>=3,0,IF(ABS(T22-R22)=2,0.5,IF(ABS(T22-R22)=1,0.75,1)))) -> 1 | W22: =AVERAGE(F22,K22,P22,U22) -> 1 | X22: =AVERAGE(G22,L22,Q22,V22) -> 1 | Y22: =+IF(W22>=0.8,1,IF(W22>=0.65,0.75,IF(W22>=0.5,0.5,IF(W22>=0.35,0.25,0)))) -> 1 | Z22: =+IF(X22>=0.8,1,IF(X22>=0.65,0.75,IF(X22>=0.5,0.5,IF(X22>=0.35,0.25,0)))) -> 1
B23: =B22+1 -> 17 | C23: =IF(ISBLANK(Data!C22),"",Data!C22) | E23: =IF(ISBLANK(Data!F59),"",IF(Data!F59=Data!E59,Data!F59,IF(MIN(ABS(Data!F59-Data!C22),ABS(Data!E59-Data!C22))=ABS(Data!F59-Data!C22),Data!F59,IF(MIN(ABS(Data!F59-Data!C22),ABS(Data!E59-Data!C22))=ABS(Data!E59-Data!C22),Data!E59,"")))) | F23: =IF(OR(C23="",D23=""),1,IF(ABS(D23-C23)>=3,0,IF(ABS(D23-C23)=2,0.5,IF(ABS(D23-C23)=1,0.75,1)))) -> 1 | G23: =IF(OR(C23="",E23=""),1,IF(ABS(E23-C23)>=3,0,IF(ABS(E23-C23)=2,0.5,IF(ABS(E23-C23)=1,0.75,1)))) -> 1 | H23: =IF(ISBLANK(Data!D22),"",Data!D22) | J23: =IF(ISBLANK(Data!F59),"",IF(Data!F59=Data!G59,Data!F59,IF(MIN(ABS(Data!F59-Data!E22),ABS(Data!G59-Data!E22))=ABS(Data!F59-Data!E22),Data!F59,IF(MIN(ABS(Data!F59-Data!E22),ABS(Data!G59-Data!E22))=ABS(Data!G59-Data!E22),Data!G59,"")))) | K23: =IF(OR(H23="",I23=""),1,IF(ABS(I23-H23)>=3,0,IF(ABS(I23-H23)=2,0.5,IF(ABS(I23-H23)=1,0.75,1)))) -> 1 | L23: =IF(OR(H23="",J23=""),1,IF(ABS(J23-H23)>=3,0,IF(ABS(J23-H23)=2,0.5,IF(ABS(J23-H23)=1,0.75,1)))) -> 1 | M23: =IF(ISBLANK(Data!E22),"",Data!E22) | N23: =IF(ISBLANK(Data!C60),"",IF(Data!C60=Data!D60,Data!C60,IF(MIN(ABS(Data!C60-Data!E22),ABS(Data!D60-Data!E22))=ABS(Data!C60-Data!E22),Data!C60,IF(MIN(ABS(Data!C60-Data!E22),ABS(Data!D60-Data!E22))=ABS(Data!D60-Data!E22),Data!D60,"")))) | O23: =IF(ISBLANK(Data!G59),"",IF(Data!G59=Data!F59,Data!G59,IF(MIN(ABS(Data!G59-Data!E22),ABS(Data!F59-Data!E22))=ABS(Data!G59-Data!E22),Data!G59,IF(MIN(ABS(Data!G59-Data!E22),ABS(Data!F59-Data!E22))=ABS(Data!F59-Data!E22),Data!F59,"")))) | P23: =IF(OR(M23="",N23=""),1,IF(ABS(N23-M23)>=3,0,IF(ABS(N23-M23)=2,0.5,IF(ABS(N23-M23)=1,0.75,1)))) -> 1 | Q23: =IF(OR(M23="",O23=""),1,IF(ABS(O23-M23)>=3,0,IF(ABS(O23-M23)=2,0.5,IF(ABS(O23-M23)=1,0.75,1)))) -> 1 | R23: =IF(ISBLANK(Data!F22),"",Data!F22) | S23: =IF(ISBLANK(Data!C60),"",IF(Data!C60=Data!D60,Data!C60,IF(MIN(ABS(Data!C60-Data!E22),ABS(Data!D60-Data!E22))=ABS(Data!C60-Data!E22),Data!C60,IF(MIN(ABS(Data!C60-Data!E22),ABS(Data!D60-Data!E22))=ABS(Data!D60-Data!E22),Data!D60,"")))) | T23: =IF(ISBLANK(Data!G59),"",IF(Data!G59=Data!G59,Data!G59,IF(MIN(ABS(Data!G59-Data!F22),ABS(Data!G59-Data!F22))=ABS(Data!G59-Data!F22),Data!G59,IF(MIN(ABS(Data!G59-Data!F22),ABS(Data!G59-Data!F22))=ABS(Data!G59-Data!F22),Data!G59,"")))) | U23: =IF(OR(R23="",S23=""),1,IF(ABS(S23-R23)>=3,0,IF(ABS(S23-R23)=2,0.5,IF(ABS(S23-R23)=1,0.75,1)))) -> 1 | V23: =IF(OR(R23="",T23=""),1,IF(ABS(T23-R23)>=3,0,IF(ABS(T23-R23)=2,0.5,IF(ABS(T23-R23)=1,0.75,1)))) -> 1 | W23: =AVERAGE(F23,K23,P23,U23) -> 1 | X23: =AVERAGE(G23,L23,Q23,V23) -> 1 | Y23: =+IF(W23>=0.8,1,IF(W23>=0.65,0.75,IF(W23>=0.5,0.5,IF(W23>=0.35,0.25,0)))) -> 1 | Z23: =+IF(X23>=0.8,1,IF(X23>=0.65,0.75,IF(X23>=0.5,0.5,IF(X23>=0.35,0.25,0)))) -> 1
